Workbook

Sheet Ene 2023
C2: Matriz Origen-Destino Tarjetas Biotren
C3: Mes: ENERO 2023 | G3: Periodo: 01 al 31 Enero
B5: 01 al 31 Enero | E5: T. Monedero
B6: Estaciones | C6: Hualqui | D6: La Leonera | E6: Manquimávida | F6: Pedro Medina | G6: Chiguayante | H6: Concepción | I6: Lorenzo Arenas | J6: UTFSM | K6: Los Cóndores | L6: Higueras | M6: El Arenal | N6: Mercado | O6: Juan Pablo II | P6: Diagonal Biobío | Q6: Alborada | R6: Costa Mar | S6: El Parque | T6: Lomas Coloradas | U6: C. Raúl Silva H. | V6: Hito Galvarino | W6: Los Canelos | X6: Huinca | Y6: Cristo Redentor | Z6: Laguna Quiñenco | AA6: Intermodal Coronel | AB6: Pasajero Lota | AC6: Concepcion Centro | AD6: Total | AF6: Estaciones | AG6: Hualqui | AH6: Leonera | AI6: Manquimavida | AJ6: Pedro Medina | AK6: Chiguayante | AL6: Concepcion | AM6: Lorenzo Arenas | AN6: UTFSM | AO6: Los Condores | AP6: Higueras | AQ6: Arenal | AR6: Mercado | AS6: Juan Pablo II | AT6: Diagonal Bio Bio | AU6: Alborada | AV6: Costa Mar | AW6: El Parque | AX6: Lomas Coloradas | AY6: Raul Silva H. | AZ6: Hito Galvarino | BA6: Los Canelos | BB6: Huinca | BC6: Cristo Redentor | BD6: Lag.Quiñenco | BE6: Coronel | BF6: Pasajero Lota | BG6: Concepcion Centro
A7: 1 | B7: Hualqui | C7: 312 | D7: 109 | E7: 142 | F7: 114 | G7: 259 | H7: 3996 | I7: 524 | J7: 512 | K7: 443 | L7: 434 | M7: 438 | N7: 563 | O7: 474 | P7: 140 | Q7: 50 | R7: 285 | S7: 156 | T7: 187 | U7: 66 | V7: 106 | W7: 71 | X7: 45 | Y7: 50 | Z7: 54 | AA7: 143 | AB7: 20 | AD7: =SUM(C7:AC7) -> 9693 | AF7: Hualqui | AG7: 290 | AH7: 340 | AI7: 340 | AJ7: 340 | AK7: 340 | AL7: 390 | AM7: 390 | AN7: 400 | AO7: 400 | AP7: 400 | AQ7: 420 | AR7: 420 | AS7: 420 | AT7: 420 | AU7: 420 | AV7: 430 | AW7: 430 | AX7: 430 | AY7: 430 | AZ7: 700 | BA7: 700 | BB7: 740 | BC7: 740 | BD7: 750 | BE7: 750 | BF7: =BE7 -> 750
A8: 2 | B8: La Leonera | C8: 161 | D8: 188 | E8: 19 | F8: 46 | G8: 130 | H8: 2065 | I8: 369 | J8: 314 | K8: 479 | L8: 429 | M8: 322 | N8: 566 | O8: 570 | P8: 48 | Q8: 69 | R8: 211 | S8: 226 | T8: 167 | U8: 87 | V8: 138 | W8: 148 | X8: 32 | Y8: 83 | Z8: 67 | AA8: 145 | AB8: 28 | AD8: =SUM(C8:AC8) -> 7107 | AF8: Leonera | AG8: 340 | AH8: 290 | AI8: 290 | AJ8: 290 | AK8: 290 | AL8: 360 | AM8: 360 | AN8: 390 | AO8: 390 | AP8: 390 | AQ8: 400 | AR8: 400 | AS8: 410 | AT8: 410 | AU8: 410 | AV8: 420 | AW8: 420 | AX8: 420 | AY8: 420 | AZ8: 690 | BA8: 690 | BB8: 700 | BC8: 700 | BD8: 700 | BE8: 700 | BF8: =BE8 -> 700
A9: 3 | B9: Manquimávida | C9: 175 | D9: 18 | E9: 140 | F9: 63 | G9: 78 | H9: 2221 | I9: 373 | J9: 248 | K9: 250 | L9: 355 | M9: 189 | N9: 429 | O9: 309 | P9: 49 | Q9: 63 | R9: 122 | S9: 88 | T9: 115 | U9: 102 | V9: 60 | W9: 114 | X9: 38 | Y9: 30 | Z9: 53 | AA9: 135 | AB9: 1 | AD9: =SUM(C9:AC9) -> 5818 | AF9: Manquimavida | AG9: 340 | AH9: 290 | AI9: 290 | AJ9: 290 | AK9: 290 | AL9: 360 | AM9: 360 | AN9: 390 | AO9: 390 | AP9: 390 | AQ9: 400 | AR9: 400 | AS9: 410 | AT9: 410 | AU9: 410 | AV9: 420 | AW9: 420 | AX9: 420 | AY9: 420 | AZ9: 690 | BA9: 690 | BB9: 700 | BC9: 700 | BD9: 700 | BE9: 700 | BF9: =BE9 -> 700
A10: 4 | B10: Pedro Medina | C10: 136 | D10: 48 | E10: 21 | F10: 74 | G10: 36 | H10: 1157 | I10: 146 | J10: 253 | K10: 234 | L10: 223 | M10: 127 | N10: 298 | O10: 167 | P10: 94 | Q10: 14 | R10: 149 | S10: 114 | T10: 95 | U10: 46 | V10: 91 | W10: 63 | X10: 17 | Y10: 70 | Z10: 20 | AA10: 87 | AB10: 4 | AD10: =SUM(C10:AC10) -> 3784 | AF10: Pedro Medina | AG10: 340 | AH10: 290 | AI10: 290 | AJ10: 290 | AK10: 290 | AL10: 360 | AM10: 360 | AN10: 390 | AO10: 390 | AP10: 390 | AQ10: 400 | AR10: 400 | AS10: 410 | AT10: 410 | AU10: 410 | AV10: 420 | AW10: 420 | AX10: 420 | AY10: 420 | AZ10: 690 | BA10: 690 | BB10: 700 | BC10: 700 | BD10: 700 | BE10: 700 | BF10: =BE10 -> 700
A11: 5 | B11: Chiguayante | C11: 437 | D11: 122 | E11: 84 | F11: 30 | G11: 254 | H11: 2147 | I11: 441 | J11: 448 | K11: 399 | L11: 563 | M11: 318 | N11: 689 | O11: 388 | P11: 164 | Q11: 34 | R11: 270 | S11: 127 | T11: 215 | U11: 101 | V11: 90 | W11: 133 | X11: 76 | Y11: 73 | Z11: 171 | AA11: 216 | AB11: 23 | AD11: =SUM(C11:AC11) -> 8013 | AF11: Chiguayante | AG11: 340 | AH11: 290 | AI11: 290 | AJ11: 290 | AK11: 290 | AL11: 360 | AM11: 360 | AN11: 390 | AO11: 390 | AP11: 390 | AQ11: 400 | AR11: 400 | AS11: 410 | AT11: 410 | AU11: 410 | AV11: 420 | AW11: 420 | AX11: 420 | AY11: 420 | AZ11: 690 | BA11: 690 | BB11: 700 | BC11: 700 | BD11: 700 | BE11: 700 | BF11: =BE11 -> 700
A12: 6 | B12: Concepción | C12: 5627 | D12: 1911 | E12: 2350 | F12: 1073 | G12: 2076 | H12: 7740 | I12: 393 | J12: 778 | K12: 2338 | L12: 1341 | M12: 1272 | N12: 1564 | O12: 1147 | P12: 703 | Q12: 1078 | R12: 6138 | S12: 2083 | T12: 8544 | U12: 7119 | V12: 3312 | W12: 8749 | X12: 4263 | Y12: 8202 | Z12: 6313 | AA12: 7391 | AB12: 547 | AD12: =SUM(C12:AC12) -> 94052 | AF12: Concepcion | AG12: 390 | AH12: 360 | AI12: 360 | AJ12: 360 | AK12: 360 | AL12: 290 | AM12: 290 | AN12: 340 | AO12: 340 | AP12: 340 | AQ12: 390 | AR12: 390 | AS12: 390 | AT12: 390 | AU12: 390 | AV12: 400 | AW12: 400 | AX12: 400 | AY12: 400 | AZ12: 650 | BA12: 650 | BB12: 650 | BC12: 650 | BD12: 670 | BE12: 670 | BF12: =BE12 -> 670
A13: 7 | B13: Lorenzo Arenas | C13: 506 | D13: 394 | E13: 307 | F13: 148 | G13: 366 | H13: 331 | I13: 138 | J13: 51 | K13: 214 | L13: 209 | M13: 155 | N13: 254 | O13: 27 | P13: 46 | Q13: 29 | R13: 172 | S13: 17 | T13: 91 | U13: 127 | V13: 57 | W13: 96 | X13: 28 | Y13: 150 | Z13: 84 | AA13: 55 | AB13: 3 | AD13: =SUM(C13:AC13) -> 4055 | AF13: Lorenzo Arenas | AG13: 390 | AH13: 360 | AI13: 360 | AJ13: 360 | AK13: 360 | AL13: 290 | AM13: 290 | AN13: 340 | AO13: 340 | AP13: 340 | AQ13: 390 | AR13: 390 | AS13: 390 | AT13: 390 | AU13: 390 | AV13: 400 | AW13: 400 | AX13: 400 | AY13: 400 | AZ13: 650 | BA13: 650 | BB13: 650 | BC13: 650 | BD13: 670 | BE13: 670 | BF13: =BE13 -> 670
A14: 8 | B14: UTFSM | C14: 549 | D14: 312 | E14: 215 | F14: 229 | G14: 465 | H14: 839 | I14: 53 | J14: 115 | K14: 100 | L14: 209 | M14: 172 | N14: 368 | O14: 74 | P14: 93 | Q14: 64 | R14: 147 | S14: 68 | T14: 142 | U14: 109 | V14: 128 | W14: 124 | X14: 111 | Y14: 95 | Z14: 91 | AA14: 158 | AB14: 11 | AD14: =SUM(C14:AC14) -> 5041 | AF14: UTFSM | AG14: 400 | AH14: 390 | AI14: 390 | AJ14: 390 | AK14: 390 | AL14: 340 | AM14: 340 | AN14: 290 | AO14: 290 | AP14: 290 | AQ14: 340 | AR14: 340 | AS14: 380 | AT14: 380 | AU14: 380 | AV14: 420 | AW14: 420 | AX14: 420 | AY14: 420 | AZ14: 660 | BA14: 660 | BB14: 670 | BC14: 670 | BD14: 690 | BE14: 690 | BF14: =BE14 -> 690
A15: 9 | B15: Los Cóndores | C15: 584 | D15: 499 | E15: 305 | F15: 203 | G15: 440 | H15: 2415 | I15: 190 | J15: 132 | K15: 135 | L15: 40 | M15: 90 | N15: 197 | O15: 191 | P15: 135 | Q15: 59 | R15: 134 | S15: 88 | T15: 208 | U15: 147 | V15: 180 | W15: 295 | X15: 49 | Y15: 82 | Z15: 164 | AA15: 289 | AB15: 99 | AD15: =SUM(C15:AC15) -> 7350 | AF15: Los Condores | AG15: 400 | AH15: 390 | AI15: 390 | AJ15: 390 | AK15: 390 | AL15: 340 | AM15: 340 | AN15: 290 | AO15: 290 | AP15: 290 | AQ15: 340 | AR15: 340 | AS15: 380 | AT15: 380 | AU15: 380 | AV15: 420 | AW15: 420 | AX15: 420 | AY15: 420 | AZ15: 660 | BA15: 660 | BB15: 670 | BC15: 670 | BD15: 690 | BE15: 690 | BF15: =BE15 -> 690
A16: 10 | B16: Higueras | C16: 406 | D16: 386 | E16: 363 | F16: 202 | G16: 419 | H16: 1607 | I16: 268 | J16: 147 | K16: 62 | L16: 91 | M16: 53 | N16: 217 | O16: 191 | P16: 85 | Q16: 54 | R16: 163 | S16: 49 | T16: 247 | U16: 202 | V16: 58 | W16: 232 | X16: 65 | Y16: 84 | Z16: 138 | AA16: 209 | AB16: 35 | AD16: =SUM(C16:AC16) -> 6033 | AF16: Higueras | AG16: 400 | AH16: 390 | AI16: 390 | AJ16: 390 | AK16: 390 | AL16: 340 | AM16: 340 | AN16: 290 | AO16: 290 | AP16: 290 | AQ16: 340 | AR16: 340 | AS16: 380 | AT16: 380 | AU16: 380 | AV16: 420 | AW16: 420 | AX16: 420 | AY16: 420 | AZ16: 660 | BA16: 660 | BB16: 670 | BC16: 670 | BD16: 690 | BE16: 690 | BF16: =BE16 -> 690
A17: 11 | B17: El Arenal | C17: 487 | D17: 286 | E17: 245 | F17: 107 | G17: 284 | H17: 1396 | I17: 136 | J17: 153 | K17: 93 | L17: 58 | M17: 118 | N17: 27 | O17: 140 | P17: 93 | Q17: 80 | R17: 161 | S17: 28 | T17: 108 | U17: 64 | V17: 113 | W17: 150 | X17: 27 | Y17: 133 | Z17: 97 | AA17: 161 | AB17: 9 | AD17: =SUM(C17:AC17) -> 4754 | AF17: Arenal | AG17: 420 | AH17: 400 | AI17: 400 | AJ17: 400 | AK17: 400 | AL17: 390 | AM17: 390 | AN17: 340 | AO17: 340 | AP17: 340 | AQ17: 290 | AR17: 290 | AS17: 380 | AT17: 380 | AU17: 380 | AV17: 420 | AW17: 420 | AX17: 420 | AY17: 420 | AZ17: 670 | BA17: 670 | BB17: 690 | BC17: 690 | BD17: 700 | BE17: 700 | BF17: =BE17 -> 700
A18: 12 | B18: Mercado | C18: 542 | D18: 477 | E18: 410 | F18: 286 | G18: 509 | H18: 1598 | I18: 281 | J18: 309 | K18: 228 | L18: 186 | M18: 28 | N18: 135 | O18: 140 | P18: 105 | Q18: 45 | R18: 211 | S18: 58 | T18: 214 | U18: 215 | V18: 111 | W18: 187 | X18: 56 | Y18: 125 | Z18: 155 | AA18: 233 | AB18: 47 | AD18: =SUM(C18:AC18) -> 6891 | AF18: Mercado | AG18: 420 | AH18: 400 | AI18: 400 | AJ18: 400 | AK18: 400 | AL18: 390 | AM18: 390 | AN18: 340 | AO18: 340 | AP18: 340 | AQ18: 290 | AR18: 290 | AS18: 380 | AT18: 380 | AU18: 380 | AV18: 420 | AW18: 420 | AX18: 420 | AY18: 420 | AZ18: 670 | BA18: 670 | BB18: 690 | BC18: 690 | BD18: 700 | BE18: 700 | BF18: =BE18 -> 700
... A31: 25 | B31: Intermodal Coronel | C31: 158 | D31: 143 | E31: 110 | F31: 45 | G31: 262 | H31: 9172 | I31: 59 | J31: 226 | K31: 385 | L31: 264 | M31: 155 | N31: 303 | O31: 4573 | P31: 1524 | Q31: 274 | R31: 1562 | S31: 900 | T31: 1685 | U31: 1264 | V31: 755 | W31: 1604 | X31: 1036 | Y31: 1832 | Z31: 1106 | AA31: 494 | AB31: 5 | AD31: =SUM(C31:AC31) -> 29896 | AF31: Coronel | AG31: 750 | AH31: 700 | AI31: 700 | AJ31: 700 | AK31: 700 | AL31: 670 | AM31: 670 | AN31: 690 | AO31: 690 | AP31: 690 | AQ31: 700 | AR31: 700 | AS31: 600 | AT31: 600 | AU31: 600 | AV31: 470 | AW31: 470 | AX31: 470 | AY31: 470 | AZ31: 380 | BA31: 380 | BB31: 290 | BC31: 290 | BD31: 290 | BE31: 290 | BF31: =BE31 -> 290
A32: 26 | B32: Pasajero Lota | C32: 5 | D32: 11 | E32: 11 | F32: 2 | G32: 18 | H32: 299 | I32: 0 | J32: 5 | K32: 30 | L32: 7 | M32: 12 | N32: 7 | O32: 219 | P32: 55 | Q32: 11 | R32: 98 | S32: 53 | T32: 81 | U32: 28 | V32: 48 | W32: 27 | X32: 35 | Y32: 37 | Z32: 19 | AA32: 12 | AB32: 27 | AD32: =SUM(C32:AC32) -> 1157 | AF32: Pasajero Lota | AG32: =AG31 -> 750 | AH32: =AH31 -> 700 | AI32: =AI31 -> 700 | AJ32: =AJ31 -> 700 | AK32: =AK31 -> 700 | AL32: =AL31 -> 670 | AM32: =AM31 -> 670 | AN32: =AN31 -> 690 | ... BF32: =BF31 -> 290
A33: 27 | B33: Concepcion Centro | AD33: =SUM(C33:AC33) -> 0 | AF33: Concepcion Centro
B34: Total | C34: =SUM(C7:C33) -> 11466 | D34: =SUM(D7:D33) -> 6208 | E34: =SUM(E7:E33) -> 5731 | F34: =SUM(F7:F33) -> 3466 | G34: =SUM(G7:G33) -> 7088 | H34: =SUM(H7:H33) -> 94962 | I34: =SUM(I7:I33) -> 4329 | J34: =SUM(J7:J33) -> 4989 | ... AC34: =SUM(AC7:AC33) -> 0 | AD34: =SUM(AD7:AD32) -> 428499
B37: =+B5 -> 01 al 31 Enero | E37: T. Estudiante
B38: Estaciones | C38: Hualqui | D38: La Leonera | E38: Manquimávida | F38: Pedro Medina | G38: Chiguayante | H38: Concepción | I38: Lorenzo Arenas | J38: UTFSM | K38: Los Cóndores | L38: Higueras | M38: El Arenal | N38: Mercado | O38: Juan Pablo II | P38: Diagonal Biobío | Q38: Alborada | R38: Costa Mar | S38: El Parque | T38: Lomas Coloradas | U38: C. Raúl Silva H. | V38: Hito Galvarino | W38: Los Canelos | X38: Huinca | Y38: Cristo Redentor | Z38: Laguna Quiñenco | AA38: Intermodal Coronel | AB38: Pasajero Lota | AC38: Concepcion Centro | AD38: Total | AF38: Estaciones | AG38: Hualqui | AH38: Leonera | AI38: Manquimavida | AJ38: Pedro Medina | AK38: Chiguayante | AL38: Concepcion | AM38: Lorenzo Arenas | AN38: UTFSM | AO38: Los Condores | AP38: Higueras | AQ38: Arenal | AR38: Mercado | AS38: Juan Pablo II | AT38: Diagonal Bio Bio | AU38: Alborada | AV38: Costa Mar | AW38: El Parque | AX38: Lomas Coloradas | AY38: Raul Silva H. | AZ38: Hito Galvarino | BA38: Los Canelos | BB38: Huinca | BC38: Cristo Redentor | BD38: Lag.Quiñenco | BE38: Coronel | BF38: Pasajero Lota | BG38: Concepcion Centro
B39: Hualqui | C39: 21 | D39: 7 | E39: 13 | F39: 4 | G39: 31 | H39: 538 | I39: 25 | J39: 23 | K39: 35 | L39: 42 | M39: 9 | N39: 24 | O39: 21 | P39: 1 | Q39: 2 | R39: 10 | S39: 17 | T39: 6 | U39: 8 | V39: 10 | W39: 4 | X39: 3 | Y39: 2 | Z39: 6 | AA39: 15 | AB39: 0 | AD39: =SUM(C39:AC39) -> 877 | AF39: Hualqui | AG39: 100 | AH39: 120 | AI39: 120 | AJ39: 120 | AK39: 120 | AL39: 130 | AM39: 130 | AN39: 130 | AO39: 130 | AP39: 130 | AQ39: 140 | AR39: 140 | AS39: 140 | AT39: 140 | AU39: 140 | AV39: 140 | AW39: 140 | AX39: 140 | AY39: 140 | AZ39: 240 | BA39: 240 | BB39: 250 | BC39: 250 | BD39: 250 | BE39: 250 | BF39: =BE39 -> 250
B40: La Leonera | C40: 11 | D40: 15 | E40: 0 | F40: 5 | G40: 7 | H40: 188 | I40: 30 | J40: 7 | K40: 16 | L40: 19 | M40: 40 | N40: 24 | O40: 13 | P40: 9 | Q40: 23 | R40: 20 | S40: 13 | T40: 10 | U40: 1 | V40: 32 | W40: 40 | X40: 4 | Y40: 19 | Z40: 19 | AA40: 12 | AB40: 0 | AD40: =SUM(C40:AC40) -> 577 | AF40: Leonera | AG40: 120 | AH40: 100 | AI40: 100 | AJ40: 100 | AK40: 100 | AL40: 120 | AM40: 120 | AN40: 130 | AO40: 130 | AP40: 130 | AQ40: 130 | AR40: 130 | AS40: 140 | AT40: 140 | AU40: 140 | AV40: 140 | AW40: 140 | AX40: 140 | AY40: 140 | AZ40: 230 | BA40: 230 | BB40: 230 | BC40: 230 | BD40: 240 | BE40: 240 | BF40: =BE40 -> 240
B41: Manquimávida | C41: 18 | D41: 0 | E41: 10 | F41: 1 | G41: 5 | H41: 190 | I41: 43 | J41: 34 | K41: 7 | L41: 25 | M41: 1 | N41: 33 | O41: 2 | P41: 0 | Q41: 18 | R41: 1 | S41: 32 | T41: 21 | U41: 3 | V41: 11 | W41: 9 | X41: 3 | Y41: 1 | Z41: 1 | AA41: 7 | AB41: 0 | AD41: =SUM(C41:AC41) -> 476 | AF41: Manquimavida | AG41: 120 | AH41: 100 | AI41: 100 | AJ41: 100 | AK41: 100 | AL41: 120 | AM41: 120 | AN41: 130 | AO41: 130 | AP41: 130 | AQ41: 130 | AR41: 130 | AS41: 140 | AT41: 140 | AU41: 140 | AV41: 140 | AW41: 140 | AX41: 140 | AY41: 140 | AZ41: 230 | BA41: 230 | BB41: 230 | BC41: 230 | BD41: 240 | BE41: 240 | BF41: =BE41 -> 240
B42: Pedro Medina | C42: 15 | D42: 7 | E42: 3 | F42: 9 | G42: 3 | H42: 81 | I42: 10 | J42: 1 | K42: 7 | L42: 60 | M42: 1 | N42: 2 | O42: 1 | P42: 1 | Q42: 10 | R42: 5 | S42: 1 | T42: 3 | U42: 0 | V42: 1 | W42: 37 | X42: 1 | Y42: 7 | Z42: 14 | AA42: 2 | AB42: 0 | AD42: =SUM(C42:AC42) -> 282 | AF42: Pedro Medina | AG42: 120 | AH42: 100 | AI42: 100 | AJ42: 100 | AK42: 100 | AL42: 120 | AM42: 120 | AN42: 130 | AO42: 130 | AP42: 130 | AQ42: 130 | AR42: 130 | AS42: 140 | AT42: 140 | AU42: 140 | AV42: 140 | AW42: 140 | AX42: 140 | AY42: 140 | AZ42: 230 | BA42: 230 | BB42: 230 | BC42: 230 | BD42: 240 | BE42: 240 | BF42: =BE42 -> 240
B43: Chiguayante | C43: 53 | D43: 12 | E43: 12 | F43: 4 | G43: 11 | H43: 284 | I43: 35 | J43: 34 | K43: 20 | L43: 46 | M43: 9 | N43: 28 | O43: 54 | P43: 17 | Q43: 2 | R43: 15 | S43: 14 | T43: 54 | U43: 15 | V43: 12 | W43: 12 | X43: 5 | Y43: 7 | Z43: 15 | AA43: 17 | AB43: 0 | AD43: =SUM(C43:AC43) -> 787 | AF43: Chiguayante | AG43: 120 | AH43: 100 | AI43: 100 | AJ43: 100 | AK43: 100 | AL43: 120 | AM43: 120 | AN43: 130 | AO43: 130 | AP43: 130 | AQ43: 130 | AR43: 130 | AS43: 140 | AT43: 140 | AU43: 140 | AV43: 140 | AW43: 140 | AX43: 140 | AY43: 140 | AZ43: 230 | BA43: 230 | BB43: 230 | BC43: 230 | BD43: 240 | BE43: 240 | BF43: =BE43 -> 240
B44: Concepción | C44: 620 | D44: 157 | E44: 181 | F44: 95 | G44: 189 | H44: 859 | I44: 49 | J44: 85 | K44: 176 | L44: 193 | M44: 119 | N44: 89 | O44: 197 | P44: 118 | Q44: 114 | R44: 740 | S44: 218 | T44: 1588 | U44: 1480 | V44: 1069 | W44: 1929 | X44: 1155 | Y44: 1706 | Z44: 1413 | AA44: 1271 | AB44: 79 | AD44: =SUM(C44:AC44) -> 15889 | AF44: Concepcion | AG44: 130 | AH44: 120 | AI44: 120 | AJ44: 120 | AK44: 120 | AL44: 100 | AM44: 100 | AN44: 120 | AO44: 120 | AP44: 120 | AQ44: 130 | AR44: 130 | AS44: 130 | AT44: 130 | AU44: 130 | AV44: 140 | AW44: 140 | AX44: 140 | AY44: 140 | AZ44: 220 | BA44: 220 | BB44: 220 | BC44: 220 | BD44: 220 | BE44: 220 | BF44: =BE44 -> 220
B45: Lorenzo Arenas | C45: 29 | D45: 15 | E45: 27 | F45: 11 | G45: 21 | H45: 26 | I45: 10 | J45: 5 | K45: 2 | L45: 31 | M45: 22 | N45: 25 | O45: 4 | P45: 10 | Q45: 5 | R45: 17 | S45: 0 | T45: 9 | U45: 22 | V45: 9 | W45: 23 | X45: 13 | Y45: 27 | Z45: 8 | AA45: 31 | AB45: 0 | AD45: =SUM(C45:AC45) -> 402 | AF45: Lorenzo Arenas | AG45: 130 | AH45: 120 | AI45: 120 | AJ45: 120 | AK45: 120 | AL45: 100 | AM45: 100 | AN45: 120 | AO45: 120 | AP45: 120 | AQ45: 130 | AR45: 130 | AS45: 130 | AT45: 130 | AU45: 130 | AV45: 140 | AW45: 140 | AX45: 140 | AY45: 140 | AZ45: 220 | BA45: 220 | BB45: 220 | BC45: 220 | BD45: 220 | BE45: 220 | BF45: =BE45 -> 220
B46: UTFSM | C46: 26 | D46: 6 | E46: 35 | F46: 2 | G46: 28 | H46: 75 | I46: 15 | J46: 10 | K46: 22 | L46: 21 | M46: 5 | N46: 10 | O46: 6 | P46: 5 | Q46: 0 | R46: 37 | S46: 2 | T46: 16 | U46: 13 | V46: 32 | W46: 38 | X46: 19 | Y46: 34 | Z46: 29 | AA46: 8 | AB46: 8 | AD46: =SUM(C46:AC46) -> 502 | AF46: UTFSM | AG46: 130 | AH46: 130 | AI46: 130 | AJ46: 130 | AK46: 130 | AL46: 120 | AM46: 120 | AN46: 100 | AO46: 100 | AP46: 100 | AQ46: 120 | AR46: 120 | AS46: 130 | AT46: 130 | AU46: 130 | AV46: 140 | AW46: 140 | AX46: 140 | AY46: 140 | AZ46: 220 | BA46: 220 | BB46: 220 | BC46: 220 | BD46: 230 | BE46: 230 | BF46: =BE46 -> 230
B47: Los Cóndores | C47: 26 | D47: 19 | E47: 13 | F47: 9 | G47: 9 | H47: 147 | I47: 8 | J47: 30 | K47: 13 | L47: 2 | M47: 4 | N47: 0 | O47: 28 | P47: 8 | Q47: 1 | R47: 11 | S47: 8 | T47: 17 | U47: 25 | V47: 40 | W47: 20 | X47: 42 | Y47: 39 | Z47: 10 | AA47: 10 | AB47: 0 | AD47: =SUM(C47:AC47) -> 539 | AF47: Los Condores | AG47: 130 | AH47: 130 | AI47: 130 | AJ47: 130 | AK47: 130 | AL47: 120 | AM47: 120 | AN47: 100 | AO47: 100 | AP47: 100 | AQ47: 120 | AR47: 120 | AS47: 130 | AT47: 130 | AU47: 130 | AV47: 140 | AW47: 140 | AX47: 140 | AY47: 140 | AZ47: 220 | BA47: 220 | BB47: 220 | BC47: 220 | BD47: 230 | BE47: 230 | BF47: =BE47 -> 230
B48: Higueras | C48: 24 | D48: 14 | E48: 14 | F48: 42 | G48: 13 | H48: 194 | I48: 9 | J48: 18 | K48: 3 | L48: 15 | M48: 1 | N48: 5 | O48: 6 | P48: 23 | Q48: 0 | R48: 10 | S48: 9 | T48: 36 | U48: 29 | V48: 15 | W48: 46 | X48: 15 | Y48: 29 | Z48: 10 | AA48: 45 | AB48: 3 | AD48: =SUM(C48:AC48) -> 628 | AF48: Higueras | AG48: 130 | AH48: 130 | AI48: 130 | AJ48: 130 | AK48: 130 | AL48: 120 | AM48: 120 | AN48: 100 | AO48: 100 | AP48: 100 | AQ48: 120 | AR48: 120 | AS48: 130 | AT48: 130 | AU48: 130 | AV48: 140 | AW48: 140 | AX48: 140 | AY48: 140 | AZ48: 220 | BA48: 220 | BB48: 220 | BC48: 220 | BD48: 230 | BE48: 230 | BF48: =BE48 -> 230
B49: El Arenal | C49: 24 | D49: 32 | E49: 0 | F49: 4 | G49: 8 | H49: 93 | I49: 32 | J49: 15 | K49: 7 | L49: 1 | M49: 6 | N49: 1 | O49: 0 | P49: 0 | Q49: 7 | R49: 9 | S49: 1 | T49: 15 | U49: 6 | V49: 8 | W49: 12 | X49: 16 | Y49: 14 | Z49: 11 | AA49: 7 | AB49: 0 | AD49: =SUM(C49:AC49) -> 329 | AF49: Arenal | AG49: 140 | AH49: 130 | AI49: 130 | AJ49: 130 | AK49: 130 | AL49: 130 | AM49: 130 | AN49: 120 | AO49: 120 | AP49: 120 | AQ49: 100 | AR49: 100 | AS49: 130 | AT49: 130 | AU49: 130 | AV49: 140 | AW49: 140 | AX49: 140 | AY49: 140 | AZ49: 220 | BA49: 220 | BB49: 230 | BC49: 230 | BD49: 230 | BE49: 230 | BF49: =BE49 -> 230
B50: Mercado | C50: 40 | D50: 24 | E50: 24 | F50: 2 | G50: 23 | H50: 99 | I50: 15 | J50: 21 | K50: 1 | L50: 16 | M50: 1 | N50: 8 | O50: 21 | P50: 3 | Q50: 2 | R50: 21 | S50: 10 | T50: 19 | U50: 10 | V50: 20 | W50: 16 | X50: 14 | Y50: 11 | Z50: 3 | AA50: 19 | AB50: 0 | AD50: =SUM(C50:AC50) -> 443 | AF50: Mercado | AG50: 140 | AH50: 130 | AI50: 130 | AJ50: 130 | AK50: 130 | AL50: 130 | AM50: 130 | AN50: 120 | AO50: 120 | AP50: 120 | AQ50: 100 | AR50: 100 | AS50: 130 | AT50: 130 | AU50: 130 | AV50: 140 | AW50: 140 | AX50: 140 | AY50: 140 | AZ50: 220 | BA50: 220 | BB50: 230 | BC50: 230 | BD50: 230 | BE50: 230 | BF50: =BE50 -> 230
... B63: Intermodal Coronel | C63: 19 | D63: 2 | E63: 1 | F63: 7 | G63: 37 | H63: 1662 | I63: 21 | J63: 25 | K63: 9 | L63: 50 | M63: 4 | N63: 21 | O63: 1079 | P63: 187 | Q63: 45 | R63: 137 | S63: 50 | T63: 196 | U63: 148 | V63: 114 | W63: 284 | X63: 173 | Y63: 292 | Z63: 215 | AA63: 54 | AB63: 1 | AD63: =SUM(C63:AC63) -> 4833 | AF63: Coronel | AG63: 250 | AH63: 240 | AI63: 240 | AJ63: 240 | AK63: 240 | AL63: 220 | AM63: 220 | AN63: 230 | AO63: 230 | AP63: 230 | AQ63: 230 | AR63: 230 | AS63: 200 | AT63: 200 | AU63: 200 | AV63: 160 | AW63: 160 | AX63: 160 | AY63: 160 | AZ63: 130 | BA63: 130 | BB63: 100 | BC63: 100 | BD63: 100 | BE63: 100 | BF63: =BE63 -> 100
B64: Pasajero Lota | C64: 1 | D64: 0 | E64: 0 | F64: 0 | G64: 0 | H64: 30 | I64: 0 | J64: 0 | K64: 0 | L64: 1 | M64: 0 | N64: 0 | O64: 35 | P64: 2 | Q64: 5 | R64: 6 | S64: 1 | T64: 10 | U64: 1 | V64: 1 | W64: 4 | X64: 4 | Y64: 8 | Z64: 3 | AA64: 2 | AB64: 2 | AD64: =SUM(C64:AC64) -> 116 | AF64: Pasajero Lota | AG64: =AG63 -> 250 | AH64: =AH63 -> 240 | AI64: =AI63 -> 240 | AJ64: =AJ63 -> 240 | AK64: =AK63 -> 240 | AL64: =AL63 -> 220 | AM64: =AM63 -> 220 | AN64: =AN63 -> 230 | ... BF64: =BF63 -> 100
B65: Concepcion Centro | AD65: =SUM(C65:AC65) -> 0 | AF65: Concepcion Centro
B66: Total | C66: =SUM(C39:C65) -> 998 | D66: =SUM(D39:D65) -> 431 | E66: =SUM(E39:E65) -> 435 | F66: =SUM(F39:F65) -> 244 | G66: =SUM(G39:G65) -> 602 | H66: =SUM(H39:H65) -> 15576 | I66: =SUM(I39:I65) -> 428 | J66: =SUM(J39:J65) -> 522 | ... AC66: =SUM(AC39:AC65) -> 0 | AD66: =SUM(C66:AC66) -> 69115
B69: =+B37 -> 01 al 31 Enero | E69: T. Tercera Edad
B70: Estaciones | C70: Hualqui | D70: La Leonera | E70: Manquimávida | F70: Pedro Medina | G70: Chiguayante | H70: Concepción | I70: Lorenzo Arenas | J70: UTFSM | K70: Los Cóndores | L70: Higueras | M70: El Arenal | N70: Mercado | O70: Juan Pablo II | P70: Diagonal Biobío | Q70: Alborada | R70: Costa Mar | S70: El Parque | T70: Lomas Coloradas | U70: C. Raúl Silva H. | V70: Hito Galvarino | W70: Los Canelos | X70: Huinca | Y70: Cristo Redentor | Z70: Laguna Quiñenco | AA70: Intermodal Coronel | AB70: Pasajero Lota | AC70: Concepcion Centro | AD70: Total | AF70: Estaciones | AG70: Hualqui | AH70: Leonera | AI70: Manquimavida | AJ70: Pedro Medina | AK70: Chiguayante | AL70: Concepcion | AM70: Lorenzo Arenas | AN70: UTFSM | AO70: Los Condores | AP70: Higueras | AQ70: Arenal | AR70: Mercado | AS70: Juan Pablo II | AT70: Diagonal Bio Bio | AU70: Alborada | AV70: Costa Mar | AW70: El Parque | AX70: Lomas Coloradas | AY70: Raul Silva H. | AZ70: Hito Galvarino | BA70: Los Canelos | BB70: Huinca | BC70: Cristo Redentor | BD70: Lag.Quiñenco | BE70: Coronel | BF70: Pasajero Lota | BG70: Concepcion Centro
...

Sheet Feb 2023
C2: Matriz Origen-Destino Tarjetas Biotren
C3: Mes: FEBRERO 2023 | G3: Periodo: 01 al 28 Febrero
B5: 01 al 28 Febrero | E5: T. Monedero
B6: Estaciones | C6: Hualqui | D6: La Leonera | E6: Manquimávida | F6: Pedro Medina | G6: Chiguayante | H6: Concepción | I6: Lorenzo Arenas | J6: UTFSM | K6: Los Cóndores | L6: Higueras | M6: El Arenal | N6: Mercado | O6: Juan Pablo II | P6: Diagonal Biobío | Q6: Alborada | R6: Costa Mar | S6: El Parque | T6: Lomas Coloradas | U6: C. Raúl Silva H. | V6: Hito Galvarino | W6: Los Canelos | X6: Huinca | Y6: Cristo Redentor | Z6: Laguna Quiñenco | AA6: Intermodal Coronel | AB6: Pasajero Lota | AC6: Concepcion Centro | AD6: Total | AF6: Estaciones | AG6: Hualqui | AH6: Leonera | AI6: Manquimavida | AJ6: Pedro Medina | AK6: Chiguayante | AL6: Concepcion | AM6: Lorenzo Arenas | AN6: UTFSM | AO6: Los Condores | AP6: Higueras | AQ6: Arenal | AR6: Mercado | AS6: Juan Pablo II | AT6: Diagonal Bio Bio | AU6: Alborada | AV6: Costa Mar | AW6: El Parque | AX6: Lomas Coloradas | AY6: Raul Silva H. | AZ6: Hito Galvarino | BA6: Los Canelos | BB6: Huinca | BC6: Cristo Redentor | BD6: Lag.Quiñenco | BE6: Coronel | BF6: Pasajero Lota | BG6: Concepcion Centro
A7: 1 | B7: Hualqui | C7: 320 | D7: 58 | E7: 59 | F7: 79 | G7: 150 | H7: 2409 | I7: 363 | J7: 328 | K7: 266 | L7: 346 | M7: 266 | N7: 355 | O7: 330 | P7: 52 | Q7: 52 | R7: 180 | S7: 123 | T7: 143 | U7: 52 | V7: 61 | W7: 50 | X7: 49 | Y7: 28 | Z7: 18 | AA7: 130 | AB7: 2 | AD7: =SUM(C7:AC7) -> 6269 | AF7: Hualqui | AG7: 290 | AH7: 340 | AI7: 340 | AJ7: 340 | AK7: 340 | AL7: 390 | AM7: 390 | AN7: 400 | AO7: 400 | AP7: 400 | AQ7: 420 | AR7: 420 | AS7: 420 | AT7: 420 | AU7: 420 | AV7: 430 | AW7: 430 | AX7: 430 | AY7: 430 | AZ7: 700 | BA7: 700 | BB7: 740 | BC7: 740 | BD7: 750 | BE7: 750 | BF7: =BE7 -> 750
A8: 2 | B8: La Leonera | C8: 148 | D8: 225 | E8: 35 | F8: 62 | G8: 95 | H8: 1409 | I8: 355 | J8: 182 | K8: 377 | L8: 367 | M8: 301 | N8: 409 | O8: 453 | P8: 27 | Q8: 61 | R8: 143 | S8: 249 | T8: 101 | U8: 51 | V8: 151 | W8: 143 | X8: 25 | Y8: 55 | Z8: 54 | AA8: 132 | AB8: 1 | AD8: =SUM(C8:AC8) -> 5611 | AF8: Leonera | AG8: 340 | AH8: 290 | AI8: 290 | AJ8: 290 | AK8: 290 | AL8: 360 | AM8: 360 | AN8: 390 | AO8: 390 | AP8: 390 | AQ8: 400 | AR8: 400 | AS8: 410 | AT8: 410 | AU8: 410 | AV8: 420 | AW8: 420 | AX8: 420 | AY8: 420 | AZ8: 690 | BA8: 690 | BB8: 700 | BC8: 700 | BD8: 700 | BE8: 700 | BF8: =BE8 -> 700
A9: 3 | B9: Manquimávida | C9: 85 | D9: 9 | E9: 227 | F9: 34 | G9: 91 | H9: 1545 | I9: 256 | J9: 155 | K9: 163 | L9: 329 | M9: 154 | N9: 307 | O9: 209 | P9: 37 | Q9: 64 | R9: 114 | S9: 102 | T9: 80 | U9: 71 | V9: 74 | W9: 82 | X9: 42 | Y9: 48 | Z9: 27 | AA9: 128 | AB9: 0 | AD9: =SUM(C9:AC9) -> 4433 | AF9: Manquimavida | AG9: 340 | AH9: 290 | AI9: 290 | AJ9: 290 | AK9: 290 | AL9: 360 | AM9: 360 | AN9: 390 | AO9: 390 | AP9: 390 | AQ9: 400 | AR9: 400 | AS9: 410 | AT9: 410 | AU9: 410 | AV9: 420 | AW9: 420 | AX9: 420 | AY9: 420 | AZ9: 690 | BA9: 690 | BB9: 700 | BC9: 700 | BD9: 700 | BE9: 700 | BF9: =BE9 -> 700
A10: 4 | B10: Pedro Medina | C10: 94 | D10: 38 | E10: 22 | F10: 113 | G10: 22 | H10: 770 | I10: 144 | J10: 183 | K10: 155 | L10: 196 | M10: 103 | N10: 215 | O10: 123 | P10: 50 | Q10: 3 | R10: 115 | S10: 147 | T10: 82 | U10: 42 | V10: 43 | W10: 50 | X10: 9 | Y10: 39 | Z10: 9 | AA10: 68 | AB10: 0 | AD10: =SUM(C10:AC10) -> 2835 | AF10: Pedro Medina | AG10: 340 | AH10: 290 | AI10: 290 | AJ10: 290 | AK10: 290 | AL10: 360 | AM10: 360 | AN10: 390 | AO10: 390 | AP10: 390 | AQ10: 400 | AR10: 400 | AS10: 410 | AT10: 410 | AU10: 410 | AV10: 420 | AW10: 420 | AX10: 420 | AY10: 420 | AZ10: 690 | BA10: 690 | BB10: 700 | BC10: 700 | BD10: 700 | BE10: 700 | BF10: =BE10 -> 700
A11: 5 | B11: Chiguayante | C11: 265 | D11: 64 | E11: 49 | F11: 13 | G11: 213 | H11: 1112 | I11: 338 | J11: 264 | K11: 319 | L11: 418 | M11: 172 | N11: 486 | O11: 155 | P11: 82 | Q11: 15 | R11: 152 | S11: 114 | T11: 112 | U11: 35 | V11: 39 | W11: 52 | X11: 54 | Y11: 65 | Z11: 44 | AA11: 145 | AB11: 2 | AD11: =SUM(C11:AC11) -> 4779 | AF11: Chiguayante | AG11: 340 | AH11: 290 | AI11: 290 | AJ11: 290 | AK11: 290 | AL11: 360 | AM11: 360 | AN11: 390 | AO11: 390 | AP11: 390 | AQ11: 400 | AR11: 400 | AS11: 410 | AT11: 410 | AU11: 410 | AV11: 420 | AW11: 420 | AX11: 420 | AY11: 420 | AZ11: 690 | BA11: 690 | BB11: 700 | BC11: 700 | BD11: 700 | BE11: 700 | BF11: =BE11 -> 700
A12: 6 | B12: Concepción | C12: 3477 | D12: 1351 | E12: 1632 | F12: 820 | G12: 1210 | H12: 5313 | I12: 331 | J12: 581 | K12: 1652 | L12: 949 | M12: 949 | N12: 1213 | O12: 892 | P12: 505 | Q12: 969 | R12: 4897 | S12: 1725 | T12: 6920 | U12: 5574 | V12: 2616 | W12: 6591 | X12: 3801 | Y12: 6811 | Z12: 4716 | AA12: 5842 | AB12: 75 | AD12: =SUM(C12:AC12) -> 71412 | AF12: Concepcion | AG12: 390 | AH12: 360 | AI12: 360 | AJ12: 360 | AK12: 360 | AL12: 290 | AM12: 290 | AN12: 340 | AO12: 340 | AP12: 340 | AQ12: 390 | AR12: 390 | AS12: 390 | AT12: 390 | AU12: 390 | AV12: 400 | AW12: 400 | AX12: 400 | AY12: 400 | AZ12: 650 | BA12: 650 | BB12: 650 | BC12: 650 | BD12: 670 | BE12: 670 | BF12: =BE12 -> 670
A13: 8 | B13: Lorenzo Arenas | C13: 324 | D13: 300 | E13: 205 | F13: 161 | G13: 301 | H13: 337 | I13: 103 | J13: 45 | K13: 144 | L13: 157 | M13: 141 | N13: 193 | O13: 16 | P13: 29 | Q13: 36 | R13: 108 | S13: 26 | T13: 55 | U13: 99 | V13: 44 | W13: 80 | X13: 21 | Y13: 98 | Z13: 56 | AA13: 56 | AB13: 0 | AD13: =SUM(C13:AC13) -> 3135 | AF13: Lorenzo Arenas | AG13: 390 | AH13: 360 | AI13: 360 | AJ13: 360 | AK13: 360 | AL13: 290 | AM13: 290 | AN13: 340 | AO13: 340 | AP13: 340 | AQ13: 390 | AR13: 390 | AS13: 390 | AT13: 390 | AU13: 390 | AV13: 400 | AW13: 400 | AX13: 400 | AY13: 400 | AZ13: 650 | BA13: 650 | BB13: 650 | BC13: 650 | BD13: 670 | BE13: 670 | BF13: =BE13 -> 670
A14: 9 | B14: UTFSM | C14: 387 | D14: 190 | E14: 138 | F14: 178 | G14: 299 | H14: 649 | I14: 56 | J14: 107 | K14: 73 | L14: 156 | M14: 93 | N14: 273 | O14: 55 | P14: 57 | Q14: 77 | R14: 140 | S14: 101 | T14: 87 | U14: 81 | V14: 123 | W14: 107 | X14: 95 | Y14: 59 | Z14: 52 | AA14: 153 | AB14: 3 | AD14: =SUM(C14:AC14) -> 3789 | AF14: UTFSM | AG14: 400 | AH14: 390 | AI14: 390 | AJ14: 390 | AK14: 390 | AL14: 340 | AM14: 340 | AN14: 290 | AO14: 290 | AP14: 290 | AQ14: 340 | AR14: 340 | AS14: 380 | AT14: 380 | AU14: 380 | AV14: 420 | AW14: 420 | AX14: 420 | AY14: 420 | AZ14: 660 | BA14: 660 | BB14: 670 | BC14: 670 | BD14: 690 | BE14: 690 | BF14: =BE14 -> 690
A15: 10 | B15: Los Cóndores | C15: 407 | D15: 392 | E15: 168 | F15: 182 | G15: 346 | H15: 1701 | I15: 118 | J15: 92 | K15: 157 | L15: 41 | M15: 69 | N15: 153 | O15: 142 | P15: 94 | Q15: 51 | R15: 109 | S15: 89 | T15: 166 | U15: 105 | V15: 140 | W15: 208 | X15: 49 | Y15: 47 | Z15: 119 | AA15: 292 | AB15: 11 | AD15: =SUM(C15:AC15) -> 5448 | AF15: Los Condores | AG15: 400 | AH15: 390 | AI15: 390 | AJ15: 390 | AK15: 390 | AL15: 340 | AM15: 340 | AN15: 290 | AO15: 290 | AP15: 290 | AQ15: 340 | AR15: 340 | AS15: 380 | AT15: 380 | AU15: 380 | AV15: 420 | AW15: 420 | AX15: 420 | AY15: 420 | AZ15: 660 | BA15: 660 | BB15: 670 | BC15: 670 | BD15: 690 | BE15: 690 | BF15: =BE15 -> 690
A16: 11 | B16: Higueras | C16: 305 | D16: 264 | E16: 283 | F16: 210 | G16: 315 | H16: 1147 | I16: 155 | J16: 103 | K16: 41 | L16: 168 | M16: 34 | N16: 167 | O16: 141 | P16: 78 | Q16: 28 | R16: 116 | S16: 68 | T16: 208 | U16: 182 | V16: 53 | W16: 191 | X16: 65 | Y16: 69 | Z16: 133 | AA16: 186 | AB16: 8 | AD16: =SUM(C16:AC16) -> 4718 | AF16: Higueras | AG16: 400 | AH16: 390 | AI16: 390 | AJ16: 390 | AK16: 390 | AL16: 340 | AM16: 340 | AN16: 290 | AO16: 290 | AP16: 290 | AQ16: 340 | AR16: 340 | AS16: 380 | AT16: 380 | AU16: 380 | AV16: 420 | AW16: 420 | AX16: 420 | AY16: 420 | AZ16: 660 | BA16: 660 | BB16: 670 | BC16: 670 | BD16: 690 | BE16: 690 | BF16: =BE16 -> 690
A17: 12 | B17: El Arenal | C17: 319 | D17: 232 | E17: 180 | F17: 149 | G17: 181 | H17: 933 | I17: 118 | J17: 101 | K17: 38 | L17: 39 | M17: 141 | N17: 20 | O17: 85 | P17: 83 | Q17: 48 | R17: 132 | S17: 23 | T17: 82 | U17: 69 | V17: 49 | W17: 138 | X17: 32 | Y17: 84 | Z17: 53 | AA17: 111 | AB17: 0 | AD17: =SUM(C17:AC17) -> 3440 | AF17: Arenal | AG17: 420 | AH17: 400 | AI17: 400 | AJ17: 400 | AK17: 400 | AL17: 390 | AM17: 390 | AN17: 340 | AO17: 340 | AP17: 340 | AQ17: 290 | AR17: 290 | AS17: 380 | AT17: 380 | AU17: 380 | AV17: 420 | AW17: 420 | AX17: 420 | AY17: 420 | AZ17: 670 | BA17: 670 | BB17: 690 | BC17: 690 | BD17: 700 | BE17: 700 | BF17: =BE17 -> 700
A18: 13 | B18: Mercado | C18: 363 | D18: 370 | E18: 303 | F18: 267 | G18: 416 | H18: 1273 | I18: 179 | J18: 214 | K18: 187 | L18: 139 | M18: 40 | N18: 148 | O18: 115 | P18: 70 | Q18: 45 | R18: 180 | S18: 45 | T18: 179 | U18: 140 | V18: 92 | W18: 201 | X18: 66 | Y18: 122 | Z18: 116 | AA18: 255 | AB18: 12 | AD18: =SUM(C18:AC18) -> 5537 | AF18: Mercado | AG18: 420 | AH18: 400 | AI18: 400 | AJ18: 400 | AK18: 400 | AL18: 390 | AM18: 390 | AN18: 340 | AO18: 340 | AP18: 340 | AQ18: 290 | AR18: 290 | AS18: 380 | AT18: 380 | AU18: 380 | AV18: 420 | AW18: 420 | AX18: 420 | AY18: 420 | AZ18: 670 | BA18: 670 | BB18: 690 | BC18: 690 | BD18: 700 | BE18: 700 | BF18: =BE18 -> 700
... A31: 26 | B31: Intermodal Coronel | C31: 152 | D31: 108 | E31: 112 | F31: 40 | G31: 163 | H31: 7228 | I31: 59 | J31: 160 | K31: 336 | L31: 185 | M31: 132 | N31: 260 | O31: 3500 | P31: 1396 | Q31: 323 | R31: 1239 | S31: 978 | T31: 1379 | U31: 974 | V31: 572 | W31: 1394 | X31: 916 | Y31: 1455 | Z31: 860 | AA31: 839 | AB31: 7 | AD31: =SUM(C31:AC31) -> 24767 | AF31: Coronel | AG31: 750 | AH31: 700 | AI31: 700 | AJ31: 700 | AK31: 700 | AL31: 670 | AM31: 670 | AN31: 690 | AO31: 690 | AP31: 690 | AQ31: 700 | AR31: 700 | AS31: 600 | AT31: 600 | AU31: 600 | AV31: 470 | AW31: 470 | AX31: 470 | AY31: 470 | AZ31: 380 | BA31: 380 | BB31: 290 | BC31: 290 | BD31: 290 | BE31: 290 | BF31: =BE31 -> 290
A32: 27 | B32: Pasajero Lota | C32: 1 | D32: 0 | E32: 0 | F32: 0 | G32: 1 | H32: 28 | I32: 0 | J32: 0 | K32: 3 | L32: 4 | M32: 3 | N32: 2 | O32: 29 | P32: 11 | Q32: 3 | R32: 18 | S32: 6 | T32: 0 | U32: 4 | V32: 11 | W32: 3 | X32: 2 | Y32: 8 | Z32: 1 | AA32: 2 | AB32: 12 | AD32: =SUM(C32:AC32) -> 152 | AF32: Pasajero Lota | AG32: =AG31 -> 750 | AH32: =AH31 -> 700 | AI32: =AI31 -> 700 | AJ32: =AJ31 -> 700 | AK32: =AK31 -> 700 | AL32: =AL31 -> 670 | AM32: =AM31 -> 670 | AN32: =AN31 -> 690 | ... BF32: =BF31 -> 290
A33: 28 | B33: Concepcion Centro | AD33: =SUM(C33:AC33) -> 0 | AF33: Concepcion Centro
B34: Total | C34: =SUM(C7:C33) -> 7534 | D34: =SUM(D7:D32) -> 4576 | E34: =SUM(E7:E32) -> 4199 | F34: =SUM(F7:F32) -> 2980 | G34: =SUM(G7:G32) -> 4732 | H34: =SUM(H7:H32) -> 71183 | I34: =SUM(I7:I32) -> 3237 | J34: =SUM(J7:J32) -> 3585 | K34: =SUM(K7:K32) -> 5253 | ... AD34: =SUM(AD7:AD32) -> 336933
B37: =+B5 -> 01 al 28 Febrero | E37: T. Estudiante
B38: Estaciones | C38: Hualqui | D38: La Leonera | E38: Manquimávida | F38: Pedro Medina | G38: Chiguayante | H38: Concepción | I38: Lorenzo Arenas | J38: UTFSM | K38: Los Cóndores | L38: Higueras | M38: El Arenal | N38: Mercado | O38: Juan Pablo II | P38: Diagonal Biobío | Q38: Alborada | R38: Costa Mar | S38: El Parque | T38: Lomas Coloradas | U38: C. Raúl Silva H. | V38: Hito Galvarino | W38: Los Canelos | X38: Huinca | Y38: Cristo Redentor | Z38: Laguna Quiñenco | AA38: Intermodal Coronel | AB38: Pasajero Lota | AC38: Concepcion Centro | AD38: Total | AF38: Estaciones | AG38: Hualqui | AH38: Leonera | AI38: Manquimavida | AJ38: Pedro Medina | AK38: Chiguayante | AL38: Concepcion | AM38: Lorenzo Arenas | AN38: UTFSM | AO38: Los Condores | AP38: Higueras | AQ38: Arenal | AR38: Mercado | AS38: Juan Pablo II | AT38: Diagonal Bio Bio | AU38: Alborada | AV38: Costa Mar | AW38: El Parque | AX38: Lomas Coloradas | AY38: Raul Silva H. | AZ38: Hito Galvarino | BA38: Los Canelos | BB38: Huinca | BC38: Cristo Redentor | BD38: Lag.Quiñenco | BE38: Coronel | BF38: Pasajero Lota | BG38: Concepcion Centro
B39: Hualqui | C39: 29 | D39: 7 | E39: 1 | F39: 2 | G39: 37 | H39: 273 | I39: 16 | J39: 13 | K39: 22 | L39: 29 | M39: 5 | N39: 8 | O39: 33 | P39: 0 | Q39: 0 | R39: 19 | S39: 15 | T39: 3 | U39: 7 | V39: 12 | W39: 3 | X39: 1 | Y39: 0 | Z39: 1 | AA39: 6 | AB39: 0 | AD39: =SUM(C39:AB39) -> 542 | AF39: Hualqui | AG39: 100 | AH39: 120 | AI39: 120 | AJ39: 120 | AK39: 120 | AL39: 130 | AM39: 130 | AN39: 130 | AO39: 130 | AP39: 130 | AQ39: 140 | AR39: 140 | AS39: 140 | AT39: 140 | AU39: 140 | AV39: 140 | AW39: 140 | AX39: 140 | AY39: 140 | AZ39: 240 | BA39: 240 | BB39: 250 | BC39: 250 | BD39: 250 | BE39: 250 | BF39: =BE39 -> 250
B40: La Leonera | C40: 10 | D40: 11 | E40: 1 | F40: 1 | G40: 3 | H40: 141 | I40: 5 | J40: 6 | K40: 13 | L40: 22 | M40: 25 | N40: 16 | O40: 24 | P40: 0 | Q40: 18 | R40: 13 | S40: 25 | T40: 8 | U40: 0 | V40: 25 | W40: 39 | X40: 4 | Y40: 13 | Z40: 3 | AA40: 9 | AB40: 0 | AD40: =SUM(C40:AB40) -> 435 | AF40: Leonera | AG40: 120 | AH40: 100 | AI40: 100 | AJ40: 100 | AK40: 100 | AL40: 120 | AM40: 120 | AN40: 130 | AO40: 130 | AP40: 130 | AQ40: 130 | AR40: 130 | AS40: 140 | AT40: 140 | AU40: 140 | AV40: 140 | AW40: 140 | AX40: 140 | AY40: 140 | AZ40: 230 | BA40: 230 | BB40: 230 | BC40: 230 | BD40: 240 | BE40: 240 | BF40: =BE40 -> 240
B41: Manquimávida | C41: 17 | D41: 1 | E41: 13 | F41: 6 | G41: 7 | H41: 110 | I41: 30 | J41: 27 | K41: 8 | L41: 13 | M41: 4 | N41: 28 | O41: 3 | P41: 0 | Q41: 11 | R41: 3 | S41: 10 | T41: 16 | U41: 15 | V41: 10 | W41: 8 | X41: 6 | Y41: 1 | Z41: 5 | AA41: 4 | AB41: 1 | AD41: =SUM(C41:AB41) -> 357 | AF41: Manquimavida | AG41: 120 | AH41: 100 | AI41: 100 | AJ41: 100 | AK41: 100 | AL41: 120 | AM41: 120 | AN41: 130 | AO41: 130 | AP41: 130 | AQ41: 130 | AR41: 130 | AS41: 140 | AT41: 140 | AU41: 140 | AV41: 140 | AW41: 140 | AX41: 140 | AY41: 140 | AZ41: 230 | BA41: 230 | BB41: 230 | BC41: 230 | BD41: 240 | BE41: 240 | BF41: =BE41 -> 240
B42: Pedro Medina | C42: 8 | D42: 4 | E42: 4 | F42: 11 | G42: 1 | H42: 54 | I42: 2 | J42: 3 | K42: 3 | L42: 30 | M42: 1 | N42: 2 | O42: 0 | P42: 1 | Q42: 1 | R42: 2 | S42: 1 | T42: 0 | U42: 1 | V42: 5 | W42: 26 | X42: 1 | Y42: 7 | Z42: 1 | AA42: 22 | AB42: 0 | AD42: =SUM(C42:AB42) -> 191 | AF42: Pedro Medina | AG42: 120 | AH42: 100 | AI42: 100 | AJ42: 100 | AK42: 100 | AL42: 120 | AM42: 120 | AN42: 130 | AO42: 130 | AP42: 130 | AQ42: 130 | AR42: 130 | AS42: 140 | AT42: 140 | AU42: 140 | AV42: 140 | AW42: 140 | AX42: 140 | AY42: 140 | AZ42: 230 | BA42: 230 | BB42: 230 | BC42: 230 | BD42: 240 | BE42: 240 | BF42: =BE42 -> 240
B43: Chiguayante | C43: 31 | D43: 3 | E43: 3 | F43: 5 | G43: 22 | H43: 95 | I43: 37 | J43: 10 | K43: 11 | L43: 43 | M43: 2 | N43: 7 | O43: 4 | P43: 1 | Q43: 0 | R43: 7 | S43: 11 | T43: 27 | U43: 12 | V43: 9 | W43: 7 | X43: 3 | Y43: 5 | Z43: 9 | AA43: 14 | AB43: 0 | AD43: =SUM(C43:AB43) -> 378 | AF43: Chiguayante | AG43: 120 | AH43: 100 | AI43: 100 | AJ43: 100 | AK43: 100 | AL43: 120 | AM43: 120 | AN43: 130 | AO43: 130 | AP43: 130 | AQ43: 130 | AR43: 130 | AS43: 140 | AT43: 140 | AU43: 140 | AV43: 140 | AW43: 140 | AX43: 140 | AY43: 140 | AZ43: 230 | BA43: 230 | BB43: 230 | BC43: 230 | BD43: 240 | BE43: 240 | BF43: =BE43 -> 240
B44: Concepción | C44: 353 | D44: 154 | E44: 142 | F44: 83 | G44: 112 | H44: 772 | I44: 44 | J44: 53 | K44: 155 | L44: 91 | M44: 76 | N44: 64 | O44: 193 | P44: 74 | Q44: 75 | R44: 592 | S44: 189 | T44: 1130 | U44: 1100 | V44: 728 | W44: 1396 | X44: 805 | Y44: 1146 | Z44: 839 | AA44: 828 | AB44: 2 | AD44: =SUM(C44:AB44) -> 11196 | AF44: Concepcion | AG44: 130 | AH44: 120 | AI44: 120 | AJ44: 120 | AK44: 120 | AL44: 100 | AM44: 100 | AN44: 120 | AO44: 120 | AP44: 120 | AQ44: 130 | AR44: 130 | AS44: 130 | AT44: 130 | AU44: 130 | AV44: 140 | AW44: 140 | AX44: 140 | AY44: 140 | AZ44: 220 | BA44: 220 | BB44: 220 | BC44: 220 | BD44: 220 | BE44: 220 | BF44: =BE44 -> 220
B45: Lorenzo Arenas | C45: 17 | D45: 2 | E45: 17 | F45: 5 | G45: 26 | H45: 31 | I45: 3 | J45: 3 | K45: 6 | L45: 19 | M45: 20 | N45: 9 | O45: 2 | P45: 2 | Q45: 14 | R45: 17 | S45: 0 | T45: 14 | U45: 17 | V45: 2 | W45: 16 | X45: 2 | Y45: 14 | Z45: 10 | AA45: 13 | AB45: 0 | AD45: =SUM(C45:AB45) -> 281 | AF45: Lorenzo Arenas | AG45: 130 | AH45: 120 | AI45: 120 | AJ45: 120 | AK45: 120 | AL45: 100 | AM45: 100 | AN45: 120 | AO45: 120 | AP45: 120 | AQ45: 130 | AR45: 130 | AS45: 130 | AT45: 130 | AU45: 130 | AV45: 140 | AW45: 140 | AX45: 140 | AY45: 140 | AZ45: 220 | BA45: 220 | BB45: 220 | BC45: 220 | BD45: 220 | BE45: 220 | BF45: =BE45 -> 220
B46: UTFSM | C46: 12 | D46: 7 | E46: 17 | F46: 3 | G46: 12 | H46: 45 | I46: 9 | J46: 17 | K46: 10 | L46: 8 | M46: 1 | N46: 18 | O46: 0 | P46: 0 | Q46: 0 | R46: 14 | S46: 5 | T46: 29 | U46: 11 | V46: 39 | W46: 39 | X46: 9 | Y46: 4 | Z46: 13 | AA46: 7 | AB46: 0 | AD46: =SUM(C46:AB46) -> 329 | AF46: UTFSM | AG46: 130 | AH46: 130 | AI46: 130 | AJ46: 130 | AK46: 130 | AL46: 120 | AM46: 120 | AN46: 100 | AO46: 100 | AP46: 100 | AQ46: 120 | AR46: 120 | AS46: 130 | AT46: 130 | AU46: 130 | AV46: 140 | AW46: 140 | AX46: 140 | AY46: 140 | AZ46: 220 | BA46: 220 | BB46: 220 | BC46: 220 | BD46: 230 | BE46: 230 | BF46: =BE46 -> 230
B47: Los Cóndores | C47: 24 | D47: 16 | E47: 11 | F47: 13 | G47: 7 | H47: 111 | I47: 2 | J47: 5 | K47: 22 | L47: 5 | M47: 2 | N47: 2 | O47: 23 | P47: 12 | Q47: 0 | R47: 7 | S47: 5 | T47: 14 | U47: 26 | V47: 32 | W47: 7 | X47: 48 | Y47: 13 | Z47: 5 | AA47: 8 | AB47: 0 | AD47: =SUM(C47:AB47) -> 420 | AF47: Los Condores | AG47: 130 | AH47: 130 | AI47: 130 | AJ47: 130 | AK47: 130 | AL47: 120 | AM47: 120 | AN47: 100 | AO47: 100 | AP47: 100 | AQ47: 120 | AR47: 120 | AS47: 130 | AT47: 130 | AU47: 130 | AV47: 140 | AW47: 140 | AX47: 140 | AY47: 140 | AZ47: 220 | BA47: 220 | BB47: 220 | BC47: 220 | BD47: 230 | BE47: 230 | BF47: =BE47 -> 230
B48: Higueras | C48: 23 | D48: 15 | E48: 9 | F48: 23 | G48: 25 | H48: 110 | I48: 4 | J48: 8 | K48: 8 | L48: 12 | M48: 1 | N48: 9 | O48: 13 | P48: 18 | Q48: 0 | R48: 5 | S48: 12 | T48: 12 | U48: 68 | V48: 17 | W48: 24 | X48: 5 | Y48: 19 | Z48: 16 | AA48: 47 | AB48: 0 | AD48: =SUM(C48:AB48) -> 503 | AF48: Higueras | AG48: 130 | AH48: 130 | AI48: 130 | AJ48: 130 | AK48: 130 | AL48: 120 | AM48: 120 | AN48: 100 | AO48: 100 | AP48: 100 | AQ48: 120 | AR48: 120 | AS48: 130 | AT48: 130 | AU48: 130 | AV48: 140 | AW48: 140 | AX48: 140 | AY48: 140 | AZ48: 220 | BA48: 220 | BB48: 220 | BC48: 220 | BD48: 230 | BE48: 230 | BF48: =BE48 -> 230
B49: El Arenal | C49: 14 | D49: 18 | E49: 3 | F49: 2 | G49: 2 | H49: 83 | I49: 20 | J49: 8 | K49: 3 | L49: 2 | M49: 9 | N49: 2 | O49: 7 | P49: 2 | Q49: 5 | R49: 11 | S49: 2 | T49: 16 | U49: 2 | V49: 20 | W49: 10 | X49: 12 | Y49: 8 | Z49: 7 | AA49: 6 | AB49: 0 | AD49: =SUM(C49:AB49) -> 274 | AF49: Arenal | AG49: 140 | AH49: 130 | AI49: 130 | AJ49: 130 | AK49: 130 | AL49: 130 | AM49: 130 | AN49: 120 | AO49: 120 | AP49: 120 | AQ49: 100 | AR49: 100 | AS49: 130 | AT49: 130 | AU49: 130 | AV49: 140 | AW49: 140 | AX49: 140 | AY49: 140 | AZ49: 220 | BA49: 220 | BB49: 230 | BC49: 230 | BD49: 230 | BE49: 230 | BF49: =BE49 -> 230
B50: Mercado | C50: 20 | D50: 12 | E50: 18 | F50: 1 | G50: 5 | H50: 62 | I50: 3 | J50: 28 | K50: 3 | L50: 17 | M50: 2 | N50: 6 | O50: 5 | P50: 1 | Q50: 3 | R50: 16 | S50: 1 | T50: 36 | U50: 13 | V50: 6 | W50: 15 | X50: 9 | Y50: 4 | Z50: 8 | AA50: 16 | AB50: 0 | AD50: =SUM(C50:AB50) -> 310 | AF50: Mercado | AG50: 140 | AH50: 130 | AI50: 130 | AJ50: 130 | AK50: 130 | AL50: 130 | AM50: 130 | AN50: 120 | AO50: 120 | AP50: 120 | AQ50: 100 | AR50: 100 | AS50: 130 | AT50: 130 | AU50: 130 | AV50: 140 | AW50: 140 | AX50: 140 | AY50: 140 | AZ50: 220 | BA50: 220 | BB50: 230 | BC50: 230 | BD50: 230 | BE50: 230 | BF50: =BE50 -> 230
... B63: Intermodal Coronel | C63: 13 | D63: 8 | E63: 6 | F63: 15 | G63: 26 | H63: 927 | I63: 8 | J63: 8 | K63: 14 | L63: 46 | M63: 2 | N63: 22 | O63: 527 | P63: 95 | Q63: 50 | R63: 92 | S63: 56 | T63: 106 | U63: 145 | V63: 100 | W63: 259 | X63: 148 | Y63: 223 | Z63: 226 | AA63: 99 | AB63: 0 | AD63: =SUM(C63:AB63) -> 3221 | AF63: Coronel | AG63: 250 | AH63: 240 | AI63: 240 | AJ63: 240 | AK63: 240 | AL63: 220 | AM63: 220 | AN63: 230 | AO63: 230 | AP63: 230 | AQ63: 230 | AR63: 230 | AS63: 200 | AT63: 200 | AU63: 200 | AV63: 160 | AW63: 160 | AX63: 160 | AY63: 160 | AZ63: 130 | BA63: 130 | BB63: 100 | BC63: 100 | BD63: 100 | BE63: 100 | BF63: =BE63 -> 100
B64: Pasajero Lota | C64: 0 | D64: 0 | E64: 0 | F64: 0 | G64: 0 | H64: 5 | I64: 0 | J64: 0 | K64: 0 | L64: 0 | M64: 0 | N64: 0 | O64: 4 | P64: 1 | Q64: 0 | R64: 0 | S64: 0 | T64: 0 | U64: 0 | V64: 0 | W64: 1 | X64: 2 | Y64: 1 | Z64: 0 | AA64: 0 | AB64: 0 | AD64: =SUM(C64:AB64) -> 14 | AF64: Pasajero Lota | AG64: =AG63 -> 250 | AH64: =AH63 -> 240 | AI64: =AI63 -> 240 | AJ64: =AJ63 -> 240 | AK64: =AK63 -> 240 | AL64: =AL63 -> 220 | AM64: =AM63 -> 220 | AN64: =AN63 -> 230 | ... BF64: =BF63 -> 100
B65: Concepcion Centro | AD65: =SUM(C65:AB65) -> 0 | AF65: Concepcion Centro
B66: Total | C66: =SUM(C39:C64) -> 648 | D66: =SUM(D39:D64) -> 350 | E66: =SUM(E39:E64) -> 307 | F66: =SUM(F39:F64) -> 209 | G66: =SUM(G39:G64) -> 393 | H66: =SUM(H39:H64) -> 10677 | I66: =SUM(I39:I64) -> 306 | J66: =SUM(J39:J64) -> 334 | ... AD66: =SUM(AD39:AD64) -> 49449
B69: =+B37 -> 01 al 28 Febrero | E69: T. Tercera Edad
B70: Estaciones | C70: Hualqui | D70: La Leonera | E70: Manquimávida | F70: Pedro Medina | G70: Chiguayante | H70: Concepción | I70: Lorenzo Arenas | J70: UTFSM | K70: Los Cóndores | L70: Higueras | M70: El Arenal | N70: Mercado | O70: Juan Pablo II | P70: Diagonal Biobío | Q70: Alborada | R70: Costa Mar | S70: El Parque | T70: Lomas Coloradas | U70: C. Raúl Silva H. | V70: Hito Galvarino | W70: Los Canelos | X70: Huinca | Y70: Cristo Redentor | Z70: Laguna Quiñenco | AA70: Intermodal Coronel | AB70: Pasajero Lota | AC70: Concepcion Centro | AD70: Total | AF70: Estaciones | AG70: Hualqui | AH70: Leonera | AI70: Manquimavida | AJ70: Pedro Medina | AK70: Chiguayante | AL70: Concepcion | AM70: Lorenzo Arenas | AN70: UTFSM | AO70: Los Condores | AP70: Higueras | AQ70: Arenal | AR70: Mercado | AS70: Juan Pablo II | AT70: Diagonal Bio Bio | AU70: Alborada | AV70: Costa Mar | AW70: El Parque | AX70: Lomas Coloradas | AY70: Raul Silva H. | AZ70: Hito Galvarino | BA70: Los Canelos | BB70: Huinca | BC70: Cristo Redentor | BD70: Lag.Quiñenco | BE70: Coronel | BF70: Pasajero Lota | BG70: Concepcion Centro
...

Sheet Mar 2023
C2: Matriz Origen-Destino Tarjetas Biotren
C3: Mes: MARZO 2023 | G3: Periodo: 01 al 31 Marzo
B5: 01 al 31 de marzo | E5: T. Monedero
B6: Estaciones | C6: Hualqui | D6: La Leonera | E6: Manquimávida | F6: Pedro Medina | G6: Chiguayante | H6: Concepción | I6: Lorenzo Arenas | J6: UTFSM | K6: Los Cóndores | L6: Higueras | M6: El Arenal | N6: Mercado | O6: Juan Pablo II | P6: Diagonal Biobío | Q6: Alborada | R6: Costa Mar | S6: El Parque | T6: Lomas Coloradas | U6: C. Raúl Silva H. | V6: Hito Galvarino | W6: Los Canelos | X6: Huinca | Y6: Cristo Redentor | Z6: Laguna Quiñenco | AA6: Intermodal Coronel | AB6: Pasajero Lota | AC6: Concepcion Centro | AD6: Total | AF6: Estaciones | AG6: Hualqui | AH6: Leonera | AI6: Manquimavida | AJ6: Pedro Medina | AK6: Chiguayante | AL6: Concepcion | AM6: Lorenzo Arenas | AN6: UTFSM | AO6: Los Condores | AP6: Higueras | AQ6: Arenal | AR6: Mercado | AS6: Juan Pablo II | AT6: Diagonal Bio Bio | AU6: Alborada | AV6: Costa Mar | AW6: El Parque | AX6: Lomas Coloradas | AY6: Raul Silva H. | AZ6: Hito Galvarino | BA6: Los Canelos | BB6: Huinca | BC6: Cristo Redentor | BD6: Lag.Quiñenco | BE6: Coronel | BF6: Pasajero Lota | BG6: Concepcion Centro
B7: Hualqui | C7: 367 | D7: 137 | E7: 287 | F7: 490 | G7: 529 | H7: 5403 | I7: 519 | J7: 726 | K7: 591 | L7: 520 | M7: 492 | N7: 421 | O7: 487 | P7: 139 | Q7: 76 | R7: 241 | S7: 168 | T7: 203 | U7: 99 | V7: 82 | W7: 79 | X7: 58 | Y7: 42 | Z7: 58 | AA7: 230 | AB7: 0 | AD7: =SUM(C7:AC7) -> 12444 | AF7: Hualqui | AG7: 290 | AH7: 340 | AI7: 340 | AJ7: 340 | AK7: 340 | AL7: 390 | AM7: 390 | AN7: 400 | AO7: 400 | AP7: 400 | AQ7: 420 | AR7: 420 | AS7: 420 | AT7: 420 | AU7: 420 | AV7: 430 | AW7: 430 | AX7: 430 | AY7: 430 | AZ7: 700 | BA7: 700 | BB7: 740 | BC7: 740 | BD7: 750 | BE7: 750 | BF7: =BE7 -> 750
B8: La Leonera | C8: 271 | D8: 232 | E8: 139 | F8: 93 | G8: 217 | H8: 3347 | I8: 678 | J8: 687 | K8: 581 | L8: 502 | M8: 387 | N8: 628 | O8: 659 | P8: 137 | Q8: 72 | R8: 188 | S8: 311 | T8: 192 | U8: 81 | V8: 194 | W8: 163 | X8: 46 | Y8: 65 | Z8: 70 | AA8: 169 | AB8: 0 | AD8: =SUM(C8:AC8) -> 10109 | AF8: Leonera | AG8: 340 | AH8: 290 | AI8: 290 | AJ8: 290 | AK8: 290 | AL8: 360 | AM8: 360 | AN8: 390 | AO8: 390 | AP8: 390 | AQ8: 400 | AR8: 400 | AS8: 410 | AT8: 410 | AU8: 410 | AV8: 420 | AW8: 420 | AX8: 420 | AY8: 420 | AZ8: 690 | BA8: 690 | BB8: 700 | BC8: 700 | BD8: 700 | BE8: 700 | BF8: =BE8 -> 700
B9: Manquimávida | C9: 404 | D9: 52 | E9: 271 | F9: 92 | G9: 200 | H9: 3955 | I9: 526 | J9: 477 | K9: 444 | L9: 519 | M9: 299 | N9: 672 | O9: 435 | P9: 108 | Q9: 96 | R9: 185 | S9: 182 | T9: 173 | U9: 141 | V9: 82 | W9: 223 | X9: 46 | Y9: 70 | Z9: 48 | AA9: 237 | AB9: 0 | AD9: =SUM(C9:AC9) -> 9937 | AF9: Manquimavida | AG9: 340 | AH9: 290 | AI9: 290 | AJ9: 290 | AK9: 290 | AL9: 360 | AM9: 360 | AN9: 390 | AO9: 390 | AP9: 390 | AQ9: 400 | AR9: 400 | AS9: 410 | AT9: 410 | AU9: 410 | AV9: 420 | AW9: 420 | AX9: 420 | AY9: 420 | AZ9: 690 | BA9: 690 | BB9: 700 | BC9: 700 | BD9: 700 | BE9: 700 | BF9: =BE9 -> 700
B10: Pedro Medina | C10: 530 | D10: 65 | E10: 125 | F10: 157 | G10: 41 | H10: 1875 | I10: 311 | J10: 463 | K10: 353 | L10: 365 | M10: 137 | N10: 467 | O10: 354 | P10: 133 | Q10: 33 | R10: 131 | S10: 209 | T10: 185 | U10: 90 | V10: 86 | W10: 53 | X10: 44 | Y10: 66 | Z10: 33 | AA10: 139 | AB10: 0 | AD10: =SUM(C10:AC10) -> 6445 | AF10: Pedro Medina | AG10: 340 | AH10: 290 | AI10: 290 | AJ10: 290 | AK10: 290 | AL10: 360 | AM10: 360 | AN10: 390 | AO10: 390 | AP10: 390 | AQ10: 400 | AR10: 400 | AS10: 410 | AT10: 410 | AU10: 410 | AV10: 420 | AW10: 420 | AX10: 420 | AY10: 420 | AZ10: 690 | BA10: 690 | BB10: 700 | BC10: 700 | BD10: 700 | BE10: 700 | BF10: =BE10 -> 700
B11: Chiguayante | C11: 764 | D11: 216 | E11: 248 | F11: 24 | G11: 382 | H11: 3231 | I11: 699 | J11: 682 | K11: 661 | L11: 766 | M11: 385 | N11: 797 | O11: 375 | P11: 167 | Q11: 33 | R11: 327 | S11: 170 | T11: 311 | U11: 107 | V11: 77 | W11: 183 | X11: 62 | Y11: 102 | Z11: 102 | AA11: 265 | AB11: 0 | AD11: =SUM(C11:AC11) -> 11136 | AF11: Chiguayante | AG11: 340 | AH11: 290 | AI11: 290 | AJ11: 290 | AK11: 290 | AL11: 360 | AM11: 360 | AN11: 390 | AO11: 390 | AP11: 390 | AQ11: 400 | AR11: 400 | AS11: 410 | AT11: 410 | AU11: 410 | AV11: 420 | AW11: 420 | AX11: 420 | AY11: 420 | AZ11: 690 | BA11: 690 | BB11: 700 | BC11: 700 | BD11: 700 | BE11: 700 | BF11: =BE11 -> 700
B12: Concepción | C12: 6590 | D12: 2440 | E12: 3568 | F12: 1653 | G12: 2474 | H12: 5969 | I12: 423 | J12: 1105 | K12: 2619 | L12: 1701 | M12: 1506 | N12: 1468 | O12: 1883 | P12: 991 | Q12: 1766 | R12: 8790 | S12: 2731 | T12: 12871 | U12: 9621 | V12: 4527 | W12: 12448 | X12: 7114 | Y12: 11366 | Z12: 9243 | AA12: 10883 | AB12: 0 | AD12: =SUM(C12:AC12) -> 125750 | AF12: Concepcion | AG12: 390 | AH12: 360 | AI12: 360 | AJ12: 360 | AK12: 360 | AL12: 290 | AM12: 290 | AN12: 340 | AO12: 340 | AP12: 340 | AQ12: 390 | AR12: 390 | AS12: 390 | AT12: 390 | AU12: 390 | AV12: 400 | AW12: 400 | AX12: 400 | AY12: 400 | AZ12: 650 | BA12: 650 | BB12: 650 | BC12: 650 | BD12: 670 | BE12: 670 | BF12: =BE12 -> 670
B13: Lorenzo Arenas | C13: 588 | D13: 440 | E13: 459 | F13: 321 | G13: 553 | H13: 466 | I13: 100 | J13: 94 | K13: 251 | L13: 285 | M13: 192 | N13: 298 | O13: 23 | P13: 35 | Q13: 40 | R13: 182 | S13: 48 | T13: 143 | U13: 134 | V13: 93 | W13: 154 | X13: 42 | Y13: 179 | Z13: 115 | AA13: 111 | AB13: 0 | AD13: =SUM(C13:AC13) -> 5346 | AF13: Lorenzo Arenas | AG13: 390 | AH13: 360 | AI13: 360 | AJ13: 360 | AK13: 360 | AL13: 290 | AM13: 290 | AN13: 340 | AO13: 340 | AP13: 340 | AQ13: 390 | AR13: 390 | AS13: 390 | AT13: 390 | AU13: 390 | AV13: 400 | AW13: 400 | AX13: 400 | AY13: 400 | AZ13: 650 | BA13: 650 | BB13: 650 | BC13: 650 | BD13: 670 | BE13: 670 | BF13: =BE13 -> 670
B14: UTFSM | C14: 823 | D14: 595 | E14: 521 | F14: 511 | G14: 704 | H14: 1277 | I14: 140 | J14: 204 | K14: 314 | L14: 489 | M14: 313 | N14: 613 | O14: 169 | P14: 118 | Q14: 136 | R14: 333 | S14: 138 | T14: 257 | U14: 206 | V14: 255 | W14: 252 | X14: 300 | Y14: 225 | Z14: 267 | AA14: 315 | AB14: 0 | AD14: =SUM(C14:AC14) -> 9475 | AF14: UTFSM | AG14: 400 | AH14: 390 | AI14: 390 | AJ14: 390 | AK14: 390 | AL14: 340 | AM14: 340 | AN14: 290 | AO14: 290 | AP14: 290 | AQ14: 340 | AR14: 340 | AS14: 380 | AT14: 380 | AU14: 380 | AV14: 420 | AW14: 420 | AX14: 420 | AY14: 420 | AZ14: 660 | BA14: 660 | BB14: 670 | BC14: 670 | BD14: 690 | BE14: 690 | BF14: =BE14 -> 690
B15: Los Cóndores | C15: 696 | D15: 714 | E15: 477 | F15: 394 | G15: 651 | H15: 2797 | I15: 293 | J15: 284 | K15: 161 | L15: 61 | M15: 136 | N15: 313 | O15: 291 | P15: 128 | Q15: 96 | R15: 253 | S15: 121 | T15: 429 | U15: 239 | V15: 243 | W15: 427 | X15: 124 | Y15: 113 | Z15: 187 | AA15: 512 | AB15: 0 | AD15: =SUM(C15:AC15) -> 10140 | AF15: Los Condores | AG15: 400 | AH15: 390 | AI15: 390 | AJ15: 390 | AK15: 390 | AL15: 340 | AM15: 340 | AN15: 290 | AO15: 290 | AP15: 290 | AQ15: 340 | AR15: 340 | AS15: 380 | AT15: 380 | AU15: 380 | AV15: 420 | AW15: 420 | AX15: 420 | AY15: 420 | AZ15: 660 | BA15: 660 | BB15: 670 | BC15: 670 | BD15: 690 | BE15: 690 | BF15: =BE15 -> 690
B16: Higueras | C16: 419 | D16: 435 | E16: 491 | F16: 409 | G16: 572 | H16: 1801 | I16: 280 | J16: 235 | K16: 59 | L16: 133 | M16: 44 | N16: 283 | O16: 300 | P16: 152 | Q16: 80 | R16: 232 | S16: 139 | T16: 317 | U16: 246 | V16: 96 | W16: 239 | X16: 141 | Y16: 141 | Z16: 231 | AA16: 303 | AB16: 0 | AD16: =SUM(C16:AC16) -> 7778 | AF16: Higueras | AG16: 400 | AH16: 390 | AI16: 390 | AJ16: 390 | AK16: 390 | AL16: 340 | AM16: 340 | AN16: 290 | AO16: 290 | AP16: 290 | AQ16: 340 | AR16: 340 | AS16: 380 | AT16: 380 | AU16: 380 | AV16: 420 | AW16: 420 | AX16: 420 | AY16: 420 | AZ16: 660 | BA16: 660 | BB16: 670 | BC16: 670 | BD16: 690 | BE16: 690 | BF16: =BE16 -> 690
B17: El Arenal | C17: 478 | D17: 353 | E17: 313 | F17: 199 | G17: 273 | H17: 1533 | I17: 172 | J17: 279 | K17: 105 | L17: 52 | M17: 137 | N17: 18 | O17: 249 | P17: 145 | Q17: 70 | R17: 172 | S17: 59 | T17: 170 | U17: 105 | V17: 122 | W17: 194 | X17: 73 | Y17: 75 | Z17: 69 | AA17: 253 | AB17: 0 | AD17: =SUM(C17:AC17) -> 5668 | AF17: Arenal | AG17: 420 | AH17: 400 | AI17: 400 | AJ17: 400 | AK17: 400 | AL17: 390 | AM17: 390 | AN17: 340 | AO17: 340 | AP17: 340 | AQ17: 290 | AR17: 290 | AS17: 380 | AT17: 380 | AU17: 380 | AV17: 420 | AW17: 420 | AX17: 420 | AY17: 420 | AZ17: 670 | BA17: 670 | BB17: 690 | BC17: 690 | BD17: 700 | BE17: 700 | BF17: =BE17 -> 700
B18: Mercado | C18: 424 | D18: 563 | E18: 575 | F18: 531 | G18: 632 | H18: 1724 | I18: 315 | J18: 503 | K18: 326 | L18: 232 | M18: 51 | N18: 177 | O18: 257 | P18: 161 | Q18: 94 | R18: 242 | S18: 75 | T18: 356 | U18: 316 | V18: 167 | W18: 350 | X18: 88 | Y18: 227 | Z18: 184 | AA18: 366 | AB18: 0 | AD18: =SUM(C18:AC18) -> 8936 | AF18: Mercado | AG18: 420 | AH18: 400 | AI18: 400 | AJ18: 400 | AK18: 400 | AL18: 390 | AM18: 390 | AN18: 340 | AO18: 340 | AP18: 340 | AQ18: 290 | AR18: 290 | AS18: 380 | AT18: 380 | AU18: 380 | AV18: 420 | AW18: 420 | AX18: 420 | AY18: 420 | AZ18: 670 | BA18: 670 | BB18: 690 | BC18: 690 | BD18: 700 | BE18: 700 | BF18: =BE18 -> 700
... B31: Intermodal Coronel | C31: 246 | D31: 124 | E31: 237 | F31: 84 | G31: 269 | H31: 14015 | I31: 131 | J31: 378 | K31: 502 | L31: 287 | M31: 236 | N31: 350 | O31: 6231 | P31: 2642 | Q31: 524 | R31: 2238 | S31: 1318 | T31: 2369 | U31: 1698 | V31: 1051 | W31: 2596 | X31: 1578 | Y31: 2514 | Z31: 1649 | AA31: 1423 | AB31: 0 | AD31: =SUM(C31:AC31) -> 44690 | AF31: Coronel | AG31: 750 | AH31: 700 | AI31: 700 | AJ31: 700 | AK31: 700 | AL31: 670 | AM31: 670 | AN31: 690 | AO31: 690 | AP31: 690 | AQ31: 700 | AR31: 700 | AS31: 600 | AT31: 600 | AU31: 600 | AV31: 470 | AW31: 470 | AX31: 470 | AY31: 470 | AZ31: 380 | BA31: 380 | BB31: 290 | BC31: 290 | BD31: 290 | BE31: 290 | BF31: =BE31 -> 290
B32: Pasajero Lota | C32: 0 | D32: 0 | E32: 0 | F32: 0 | G32: 0 | H32: 0 | I32: 0 | J32: 0 | K32: 0 | L32: 0 | M32: 0 | N32: 0 | O32: 0 | P32: 0 | Q32: 0 | R32: 0 | S32: 0 | T32: 0 | U32: 0 | V32: 0 | W32: 0 | X32: 0 | Y32: 0 | Z32: 0 | AA32: 0 | AB32: 0 | AD32: =SUM(C32:AC32) -> 0 | AF32: Pasajero Lota | AG32: =AG31 -> 750 | AH32: =AH31 -> 700 | AI32: =AI31 -> 700 | AJ32: =AJ31 -> 700 | AK32: =AK31 -> 700 | AL32: =AL31 -> 670 | AM32: =AM31 -> 670 | AN32: =AN31 -> 690 | ... BF32: =BF31 -> 290
B33: Concepcion Centro | AD33: =SUM(C33:AC33) -> 0 | AF33: Concepcion Centro
B34: Total | C34: =SUM(C7:C33) -> 14079 | D34: =SUM(D7:D32) -> 7689 | E34: =SUM(E7:E32) -> 9201 | F34: =SUM(F7:F32) -> 6210 | G34: =SUM(G7:G32) -> 9180 | H34: =SUM(H7:H32) -> 135320 | I34: =SUM(I7:I32) -> 6113 | J34: =SUM(J7:J32) -> 8989 | K34: =SUM(K7:K32) -> 9507 | ... AD34: =SUM(AD7:AD32) -> 615856
B37: 01 al 31 de marzo | E37: T. Estudiante
B38: Estaciones | C38: Hualqui | D38: La Leonera | E38: Manquimávida | F38: Pedro Medina | G38: Chiguayante | H38: Concepción | I38: Lorenzo Arenas | J38: UTFSM | K38: Los Cóndores | L38: Higueras | M38: El Arenal | N38: Mercado | O38: Juan Pablo II | P38: Diagonal Biobío | Q38: Alborada | R38: Costa Mar | S38: El Parque | T38: Lomas Coloradas | U38: C. Raúl Silva H. | V38: Hito Galvarino | W38: Los Canelos | X38: Huinca | Y38: Cristo Redentor | Z38: Laguna Quiñenco | AA38: Intermodal Coronel | AB38: Pasajero Lota | AC38: Concepcion Centro | AD38: Total | AF38: Estaciones | AG38: Hualqui | AH38: Leonera | AI38: Manquimavida | AJ38: Pedro Medina | AK38: Chiguayante | AL38: Concepcion | AM38: Lorenzo Arenas | AN38: UTFSM | AO38: Los Condores | AP38: Higueras | AQ38: Arenal | AR38: Mercado | AS38: Juan Pablo II | AT38: Diagonal Bio Bio | AU38: Alborada | AV38: Costa Mar | AW38: El Parque | AX38: Lomas Coloradas | AY38: Raul Silva H. | AZ38: Hito Galvarino | BA38: Los Canelos | BB38: Huinca | BC38: Cristo Redentor | BD38: Lag.Quiñenco | BE38: Coronel | BF38: Pasajero Lota | BG38: Concepcion Centro
B39: Hualqui | C39: 39 | D39: 5 | E39: 82 | F39: 329 | G39: 122 | H39: 1103 | I39: 43 | J39: 172 | K39: 67 | L39: 51 | M39: 16 | N39: 11 | O39: 34 | P39: 37 | Q39: 0 | R39: 36 | S39: 14 | T39: 4 | U39: 12 | V39: 20 | W39: 2 | X39: 2 | Y39: 1 | Z39: 2 | AA39: 5 | AB39: 0 | AD39: =SUM(C39:AB39) -> 2209 | AF39: Hualqui | AG39: 100 | AH39: 120 | AI39: 120 | AJ39: 120 | AK39: 120 | AL39: 130 | AM39: 130 | AN39: 130 | AO39: 130 | AP39: 130 | AQ39: 140 | AR39: 140 | AS39: 140 | AT39: 140 | AU39: 140 | AV39: 140 | AW39: 140 | AX39: 140 | AY39: 140 | AZ39: 240 | BA39: 240 | BB39: 250 | BC39: 250 | BD39: 250 | BE39: 250 | BF39: =BE39 -> 250
B40: La Leonera | C40: 24 | D40: 14 | E40: 36 | F40: 5 | G40: 33 | H40: 355 | I40: 10 | J40: 151 | K40: 11 | L40: 41 | M40: 30 | N40: 34 | O40: 14 | P40: 7 | Q40: 2 | R40: 8 | S40: 24 | T40: 19 | U40: 6 | V40: 21 | W40: 35 | X40: 4 | Y40: 10 | Z40: 3 | AA40: 14 | AB40: 0 | AD40: =SUM(C40:AB40) -> 911 | AF40: Leonera | AG40: 120 | AH40: 100 | AI40: 100 | AJ40: 100 | AK40: 100 | AL40: 120 | AM40: 120 | AN40: 130 | AO40: 130 | AP40: 130 | AQ40: 130 | AR40: 130 | AS40: 140 | AT40: 140 | AU40: 140 | AV40: 140 | AW40: 140 | AX40: 140 | AY40: 140 | AZ40: 230 | BA40: 230 | BB40: 230 | BC40: 230 | BD40: 240 | BE40: 240 | BF40: =BE40 -> 240
B41: Manquimávida | C41: 116 | D41: 18 | E41: 21 | F41: 22 | G41: 36 | H41: 367 | I41: 29 | J41: 151 | K41: 14 | L41: 36 | M41: 5 | N41: 26 | O41: 4 | P41: 15 | Q41: 2 | R41: 8 | S41: 2 | T41: 35 | U41: 26 | V41: 13 | W41: 12 | X41: 9 | Y41: 0 | Z41: 6 | AA41: 3 | AB41: 0 | AD41: =SUM(C41:AB41) -> 976 | AF41: Manquimavida | AG41: 120 | AH41: 100 | AI41: 100 | AJ41: 100 | AK41: 100 | AL41: 120 | AM41: 120 | AN41: 130 | AO41: 130 | AP41: 130 | AQ41: 130 | AR41: 130 | AS41: 140 | AT41: 140 | AU41: 140 | AV41: 140 | AW41: 140 | AX41: 140 | AY41: 140 | AZ41: 230 | BA41: 230 | BB41: 230 | BC41: 230 | BD41: 240 | BE41: 240 | BF41: =BE41 -> 240
B42: Pedro Medina | C42: 283 | D42: 7 | E42: 29 | F42: 27 | G42: 4 | H42: 178 | I42: 6 | J42: 96 | K42: 13 | L42: 55 | M42: 1 | N42: 16 | O42: 4 | P42: 7 | Q42: 8 | R42: 8 | S42: 0 | T42: 3 | U42: 15 | V42: 18 | W42: 37 | X42: 0 | Y42: 11 | Z42: 7 | AA42: 12 | AB42: 0 | AD42: =SUM(C42:AB42) -> 845 | AF42: Pedro Medina | AG42: 120 | AH42: 100 | AI42: 100 | AJ42: 100 | AK42: 100 | AL42: 120 | AM42: 120 | AN42: 130 | AO42: 130 | AP42: 130 | AQ42: 130 | AR42: 130 | AS42: 140 | AT42: 140 | AU42: 140 | AV42: 140 | AW42: 140 | AX42: 140 | AY42: 140 | AZ42: 230 | BA42: 230 | BB42: 230 | BC42: 230 | BD42: 240 | BE42: 240 | BF42: =BE42 -> 240
B43: Chiguayante | C43: 145 | D43: 13 | E43: 20 | F43: 3 | G43: 21 | H43: 243 | I43: 43 | J43: 240 | K43: 42 | L43: 106 | M43: 22 | N43: 19 | O43: 25 | P43: 6 | Q43: 12 | R43: 28 | S43: 23 | T43: 49 | U43: 14 | V43: 32 | W43: 16 | X43: 3 | Y43: 3 | Z43: 2 | AA43: 13 | AB43: 0 | AD43: =SUM(C43:AB43) -> 1143 | AF43: Chiguayante | AG43: 120 | AH43: 100 | AI43: 100 | AJ43: 100 | AK43: 100 | AL43: 120 | AM43: 120 | AN43: 130 | AO43: 130 | AP43: 130 | AQ43: 130 | AR43: 130 | AS43: 140 | AT43: 140 | AU43: 140 | AV43: 140 | AW43: 140 | AX43: 140 | AY43: 140 | AZ43: 230 | BA43: 230 | BB43: 230 | BC43: 230 | BD43: 240 | BE43: 240 | BF43: =BE43 -> 240
