Workbook

Sheet CortoLaja 2025
A1: Matriz Tarifaria Adulto
A2: Estaciónes | B2: Mercado | C2: Arenal | D2: Higueras | E2: Los Condores | F2: UTFSM | G2: Lorenzo Arenas | H2: Concepción | I2: Chiguayante | J2: Predro Medina | K2: Manquimávida | L2: La leonera | M2: Hualqui | N2: Quilacoya | O2: San Miguel | P2: Unihue | Q2: Valle Chanco | R2: Los Acacios | S2: Talcamávida | T2: Gomero | U2: Buenuraqui | V2: San Rosendo | W2: Laja
A3: Mercado | B3: 0 | C3: 550 | D3: 550 | E3: 550 | F3: 550 | G3: 550 | H3: 550 | I3: 550 | J3: 550 | K3: 550 | L3: 550 | M3: 550 | N3: 1170 | O3: 1170 | P3: 1300 | Q3: 1300 | R3: 1300 | S3: 1300 | T3: 1300 | U3: 2030 | V3: 2170 | W3: 2170
A4: Arenal | B4: 550 | C4: 0 | D4: 550 | E4: 550 | F4: 550 | G4: 550 | H4: 550 | I4: 550 | J4: 550 | K4: 550 | L4: 550 | M4: 550 | N4: 1170 | O4: 1170 | P4: 1300 | Q4: 1300 | R4: 1300 | S4: 1300 | T4: 1300 | U4: 2030 | V4: 2170 | W4: 2170
A5: Higueras | B5: 550 | C5: 550 | D5: 0 | E5: 550 | F5: 550 | G5: 550 | H5: 550 | I5: 550 | J5: 550 | K5: 550 | L5: 550 | M5: 550 | N5: 1170 | O5: 1170 | P5: 1300 | Q5: 1300 | R5: 1300 | S5: 1300 | T5: 1300 | U5: 2030 | V5: 2170 | W5: 2170
A6: Los Condores | B6: 550 | C6: 550 | D6: 550 | E6: 0 | F6: 550 | G6: 550 | H6: 550 | I6: 550 | J6: 550 | K6: 550 | L6: 550 | M6: 550 | N6: 1170 | O6: 1170 | P6: 1300 | Q6: 1300 | R6: 1300 | S6: 1300 | T6: 1300 | U6: 2030 | V6: 2170 | W6: 2170
A7: UTFSM | B7: 550 | C7: 550 | D7: 550 | E7: 550 | F7: 0 | G7: 550 | H7: 550 | I7: 550 | J7: 550 | K7: 550 | L7: 550 | M7: 550 | N7: 1170 | O7: 1170 | P7: 1300 | Q7: 1300 | R7: 1300 | S7: 1300 | T7: 1300 | U7: 2030 | V7: 2170 | W7: 2170
A8: Lorenzo Arenas | B8: 550 | C8: 550 | D8: 550 | E8: 550 | F8: 550 | G8: 0 | H8: 550 | I8: 550 | J8: 550 | K8: 550 | L8: 550 | M8: 550 | N8: 1170 | O8: 1170 | P8: 1300 | Q8: 1300 | R8: 1300 | S8: 1300 | T8: 1300 | U8: 2030 | V8: 2170 | W8: 2170
A9: Concepción | B9: 550 | C9: 550 | D9: 550 | E9: 550 | F9: 550 | G9: 550 | H9: 0 | I9: 550 | J9: 550 | K9: 550 | L9: 550 | M9: 550 | N9: 1170 | O9: 1170 | P9: 1300 | Q9: 1300 | R9: 1300 | S9: 1300 | T9: 1300 | U9: 2030 | V9: 2170 | W9: 2170
A10: Chiguayante | B10: 550 | C10: 550 | D10: 550 | E10: 550 | F10: 550 | G10: 550 | H10: 550 | I10: 0 | J10: 550 | K10: 550 | L10: 550 | M10: 550 | N10: 1170 | O10: 1170 | P10: 1300 | Q10: 1300 | R10: 1300 | S10: 1300 | T10: 1300 | U10: 2030 | V10: 2170 | W10: 2170
A11: Pedro Medina | B11: 550 | C11: 550 | D11: 550 | E11: 550 | F11: 550 | G11: 550 | H11: 550 | I11: 550 | J11: 0 | K11: 550 | L11: 550 | M11: 550 | N11: 1170 | O11: 1170 | P11: 1300 | Q11: 1300 | R11: 1300 | S11: 1300 | T11: 1300 | U11: 2030 | V11: 2170 | W11: 2170
A12: Manquimávida | B12: 550 | C12: 550 | D12: 550 | E12: 550 | F12: 550 | G12: 550 | H12: 550 | I12: 550 | J12: 550 | K12: 0 | L12: 550 | M12: 550 | N12: 1170 | O12: 1170 | P12: 1300 | Q12: 1300 | R12: 1300 | S12: 1300 | T12: 1300 | U12: 2030 | V12: 2170 | W12: 2170
A13: La Leonera | B13: 550 | C13: 550 | D13: 550 | E13: 550 | F13: 550 | G13: 550 | H13: 550 | I13: 550 | J13: 550 | K13: 550 | L13: 0 | M13: 550 | N13: 1170 | O13: 1170 | P13: 1300 | Q13: 1300 | R13: 1300 | S13: 1300 | T13: 1300 | U13: 2030 | V13: 2170 | W13: 2170
A14: Hualqui | B14: 550 | C14: 550 | D14: 550 | E14: 550 | F14: 550 | G14: 550 | H14: 550 | I14: 550 | J14: 550 | K14: 550 | L14: 550 | M14: 0 | N14: 650 | O14: 650 | P14: 1300 | Q14: 1300 | R14: 1300 | S14: 1300 | T14: 1300 | U14: 2030 | V14: 2170 | W14: 2170
... A24: Laja | B24: 2170 | C24: 2170 | D24: 2170 | E24: 2170 | F24: 2170 | G24: 2170 | H24: 2170 | I24: 2170 | J24: 2170 | K24: 2170 | L24: 2170 | M24: 2170 | N24: 1840 | O24: 1840 | P24: 1200 | Q24: 1200 | R24: 1200 | S24: 1200 | T24: 1200 | U24: 1200 | V24: 650 | W24: 0
A25: 0.5
A26: Matriz Tarifaria Estudiante Media y Superior
A27: Estaciónes | B27: Mercado | C27: Arenal | D27: Higueras | E27: Los Condores | F27: UTFSM | G27: Lorenzo Arenas | H27: Concepción | I27: Chiguayante | J27: Predro Medina | K27: Manquimávida | L27: La leonera | M27: Hualqui | N27: Quilacoya | O27: San Miguel | P27: Unihue | Q27: Valle Chanco | R27: Los Acacios | S27: Talcamávida | T27: Gomero | U27: Buenuraqui | V27: San Rosendo | W27: Laja
A28: Mercado | B28: =MROUND(B3*$A$25,10) -> 0 | C28: =MROUND(C3*$A$25,10) -> 280 | D28: =MROUND(D3*$A$25,10) -> 280 | E28: =MROUND(E3*$A$25,10) -> 280 | F28: =MROUND(F3*$A$25,10) -> 280 | G28: =MROUND(G3*$A$25,10) -> 280 | H28: =MROUND(H3*$A$25,10) -> 280 | I28: =MROUND(I3*$A$25,10) -> 280 | ... W28: =MROUND(W3*$A$25,10) -> 1090
A29: Arenal | B29: =MROUND(B4*$A$25,10) -> 280 | C29: =MROUND(C4*$A$25,10) -> 0 | D29: =MROUND(D4*$A$25,10) -> 280 | E29: =MROUND(E4*$A$25,10) -> 280 | F29: =MROUND(F4*$A$25,10) -> 280 | G29: =MROUND(G4*$A$25,10) -> 280 | H29: =MROUND(H4*$A$25,10) -> 280 | I29: =MROUND(I4*$A$25,10) -> 280 | ... W29: =MROUND(W4*$A$25,10) -> 1090
A30: Higueras | B30: =MROUND(B5*$A$25,10) -> 280 | C30: =MROUND(C5*$A$25,10) -> 280 | D30: =MROUND(D5*$A$25,10) -> 0 | E30: =MROUND(E5*$A$25,10) -> 280 | F30: =MROUND(F5*$A$25,10) -> 280 | G30: =MROUND(G5*$A$25,10) -> 280 | H30: =MROUND(H5*$A$25,10) -> 280 | I30: =MROUND(I5*$A$25,10) -> 280 | ... W30: =MROUND(W5*$A$25,10) -> 1090
A31: Los Condores | B31: =MROUND(B6*$A$25,10) -> 280 | C31: =MROUND(C6*$A$25,10) -> 280 | D31: =MROUND(D6*$A$25,10) -> 280 | E31: =MROUND(E6*$A$25,10) -> 0 | F31: =MROUND(F6*$A$25,10) -> 280 | G31: =MROUND(G6*$A$25,10) -> 280 | H31: =MROUND(H6*$A$25,10) -> 280 | I31: =MROUND(I6*$A$25,10) -> 280 | ... W31: =MROUND(W6*$A$25,10) -> 1090
A32: UTFSM | B32: =MROUND(B7*$A$25,10) -> 280 | C32: =MROUND(C7*$A$25,10) -> 280 | D32: =MROUND(D7*$A$25,10) -> 280 | E32: =MROUND(E7*$A$25,10) -> 280 | F32: =MROUND(F7*$A$25,10) -> 0 | G32: =MROUND(G7*$A$25,10) -> 280 | H32: =MROUND(H7*$A$25,10) -> 280 | I32: =MROUND(I7*$A$25,10) -> 280 | ... W32: =MROUND(W7*$A$25,10) -> 1090
A33: Lorenzo Arenas | B33: =MROUND(B8*$A$25,10) -> 280 | C33: =MROUND(C8*$A$25,10) -> 280 | D33: =MROUND(D8*$A$25,10) -> 280 | E33: =MROUND(E8*$A$25,10) -> 280 | F33: =MROUND(F8*$A$25,10) -> 280 | G33: =MROUND(G8*$A$25,10) -> 0 | H33: =MROUND(H8*$A$25,10) -> 280 | I33: =MROUND(I8*$A$25,10) -> 280 | ... W33: =MROUND(W8*$A$25,10) -> 1090
A34: Concepción | B34: =MROUND(B9*$A$25,10) -> 280 | C34: =MROUND(C9*$A$25,10) -> 280 | D34: =MROUND(D9*$A$25,10) -> 280 | E34: =MROUND(E9*$A$25,10) -> 280 | F34: =MROUND(F9*$A$25,10) -> 280 | G34: =MROUND(G9*$A$25,10) -> 280 | H34: =MROUND(H9*$A$25,10) -> 0 | I34: =MROUND(I9*$A$25,10) -> 280 | ... W34: =MROUND(W9*$A$25,10) -> 1090
A35: Chiguayante | B35: =MROUND(B10*$A$25,10) -> 280 | C35: =MROUND(C10*$A$25,10) -> 280 | D35: =MROUND(D10*$A$25,10) -> 280 | E35: =MROUND(E10*$A$25,10) -> 280 | F35: =MROUND(F10*$A$25,10) -> 280 | G35: =MROUND(G10*$A$25,10) -> 280 | H35: =MROUND(H10*$A$25,10) -> 280 | I35: =MROUND(I10*$A$25,10) -> 0 | ... W35: =MROUND(W10*$A$25,10) -> 1090
A36: Pedro Medina | B36: =MROUND(B11*$A$25,10) -> 280 | C36: =MROUND(C11*$A$25,10) -> 280 | D36: =MROUND(D11*$A$25,10) -> 280 | E36: =MROUND(E11*$A$25,10) -> 280 | F36: =MROUND(F11*$A$25,10) -> 280 | G36: =MROUND(G11*$A$25,10) -> 280 | H36: =MROUND(H11*$A$25,10) -> 280 | I36: =MROUND(I11*$A$25,10) -> 280 | ... W36: =MROUND(W11*$A$25,10) -> 1090
A37: Manquimávida | B37: =MROUND(B12*$A$25,10) -> 280 | C37: =MROUND(C12*$A$25,10) -> 280 | D37: =MROUND(D12*$A$25,10) -> 280 | E37: =MROUND(E12*$A$25,10) -> 280 | F37: =MROUND(F12*$A$25,10) -> 280 | G37: =MROUND(G12*$A$25,10) -> 280 | H37: =MROUND(H12*$A$25,10) -> 280 | I37: =MROUND(I12*$A$25,10) -> 280 | ... W37: =MROUND(W12*$A$25,10) -> 1090
A38: La Leonera | B38: =MROUND(B13*$A$25,10) -> 280 | C38: =MROUND(C13*$A$25,10) -> 280 | D38: =MROUND(D13*$A$25,10) -> 280 | E38: =MROUND(E13*$A$25,10) -> 280 | F38: =MROUND(F13*$A$25,10) -> 280 | G38: =MROUND(G13*$A$25,10) -> 280 | H38: =MROUND(H13*$A$25,10) -> 280 | I38: =MROUND(I13*$A$25,10) -> 280 | ... W38: =MROUND(W13*$A$25,10) -> 1090
A39: Hualqui | B39: =MROUND(B14*$A$25,10) -> 280 | C39: =MROUND(C14*$A$25,10) -> 280 | D39: =MROUND(D14*$A$25,10) -> 280 | E39: =MROUND(E14*$A$25,10) -> 280 | F39: =MROUND(F14*$A$25,10) -> 280 | G39: =MROUND(G14*$A$25,10) -> 280 | H39: =MROUND(H14*$A$25,10) -> 280 | I39: =MROUND(I14*$A$25,10) -> 280 | ... W39: =MROUND(W14*$A$25,10) -> 1090
... A49: Laja | B49: =MROUND(B24*$A$25,10) -> 1090 | C49: =MROUND(C24*$A$25,10) -> 1090 | D49: =MROUND(D24*$A$25,10) -> 1090 | E49: =MROUND(E24*$A$25,10) -> 1090 | F49: =MROUND(F24*$A$25,10) -> 1090 | G49: =MROUND(G24*$A$25,10) -> 1090 | H49: =MROUND(H24*$A$25,10) -> 1090 | I49: =MROUND(I24*$A$25,10) -> 1090 | ... W49: =MROUND(W24*$A$25,10) -> 0
A51: Matriz Tarifaria Tercera Edad
A52: Estaciónes | B52: Mercado | C52: Arenal | D52: Higueras | E52: Los Condores | F52: UTFSM | G52: Lorenzo Arenas | H52: Concepción | I52: Chiguayante | J52: Predro Medina | K52: Manquimávida | L52: La leonera | M52: Hualqui | N52: Quilacoya | O52: San Miguel | P52: Unihue | Q52: Valle Chanco | R52: Los Acacios | S52: Talcamávida | T52: Gomero | U52: Buenuraqui | V52: San Rosendo | W52: Laja
A53: Mercado | B53: =MROUND(B3*$A$25,10) -> 0 | C53: =MROUND(C3*$A$25,10) -> 280 | D53: =MROUND(D3*$A$25,10) -> 280 | E53: =MROUND(E3*$A$25,10) -> 280 | F53: =MROUND(F3*$A$25,10) -> 280 | G53: =MROUND(G3*$A$25,10) -> 280 | H53: =MROUND(H3*$A$25,10) -> 280 | I53: =MROUND(I3*$A$25,10) -> 280 | ... W53: =MROUND(W3*$A$25,10) -> 1090
A54: Arenal | B54: =MROUND(B4*$A$25,10) -> 280 | C54: =MROUND(C4*$A$25,10) -> 0 | D54: =MROUND(D4*$A$25,10) -> 280 | E54: =MROUND(E4*$A$25,10) -> 280 | F54: =MROUND(F4*$A$25,10) -> 280 | G54: =MROUND(G4*$A$25,10) -> 280 | H54: =MROUND(H4*$A$25,10) -> 280 | I54: =MROUND(I4*$A$25,10) -> 280 | ... W54: =MROUND(W4*$A$25,10) -> 1090
A55: Higueras | B55: =MROUND(B5*$A$25,10) -> 280 | C55: =MROUND(C5*$A$25,10) -> 280 | D55: =MROUND(D5*$A$25,10) -> 0 | E55: =MROUND(E5*$A$25,10) -> 280 | F55: =MROUND(F5*$A$25,10) -> 280 | G55: =MROUND(G5*$A$25,10) -> 280 | H55: =MROUND(H5*$A$25,10) -> 280 | I55: =MROUND(I5*$A$25,10) -> 280 | ... W55: =MROUND(W5*$A$25,10) -> 1090
A56: Los Condores | B56: =MROUND(B6*$A$25,10) -> 280 | C56: =MROUND(C6*$A$25,10) -> 280 | D56: =MROUND(D6*$A$25,10) -> 280 | E56: =MROUND(E6*$A$25,10) -> 0 | F56: =MROUND(F6*$A$25,10) -> 280 | G56: =MROUND(G6*$A$25,10) -> 280 | H56: =MROUND(H6*$A$25,10) -> 280 | I56: =MROUND(I6*$A$25,10) -> 280 | ... W56: =MROUND(W6*$A$25,10) -> 1090
A57: UTFSM | B57: =MROUND(B7*$A$25,10) -> 280 | C57: =MROUND(C7*$A$25,10) -> 280 | D57: =MROUND(D7*$A$25,10) -> 280 | E57: =MROUND(E7*$A$25,10) -> 280 | F57: =MROUND(F7*$A$25,10) -> 0 | G57: =MROUND(G7*$A$25,10) -> 280 | H57: =MROUND(H7*$A$25,10) -> 280 | I57: =MROUND(I7*$A$25,10) -> 280 | ... W57: =MROUND(W7*$A$25,10) -> 1090
A58: Lorenzo Arenas | B58: =MROUND(B8*$A$25,10) -> 280 | C58: =MROUND(C8*$A$25,10) -> 280 | D58: =MROUND(D8*$A$25,10) -> 280 | E58: =MROUND(E8*$A$25,10) -> 280 | F58: =MROUND(F8*$A$25,10) -> 280 | G58: =MROUND(G8*$A$25,10) -> 0 | H58: =MROUND(H8*$A$25,10) -> 280 | I58: =MROUND(I8*$A$25,10) -> 280 | ... W58: =MROUND(W8*$A$25,10) -> 1090
A59: Concepción | B59: =MROUND(B9*$A$25,10) -> 280 | C59: =MROUND(C9*$A$25,10) -> 280 | D59: =MROUND(D9*$A$25,10) -> 280 | E59: =MROUND(E9*$A$25,10) -> 280 | F59: =MROUND(F9*$A$25,10) -> 280 | G59: =MROUND(G9*$A$25,10) -> 280 | H59: =MROUND(H9*$A$25,10) -> 0 | I59: =MROUND(I9*$A$25,10) -> 280 | ... W59: =MROUND(W9*$A$25,10) -> 1090
...

Sheet Hoja1
A1: ID | B1: 1 | C1: 2 | D1: 3 | E1: 4 | F1: 5 | G1: 6 | H1: 7 | I1: 8 | J1: 9 | K1: 10 | L1: 11 | M1: 12 | N1: 13 | O1: 14 | P1: 15 | Q1: 16 | R1: 17 | S1: 18 | T1: 19 | U1: 20 | V1: 21 | W1: 22
A2: 1 | B2: 0 | C2: 70 | D2: 70 | E2: 70 | F2: 70 | G2: 70 | H2: 70 | I2: 70 | J2: 70 | K2: 70 | L2: 70 | M2: 70 | N2: 230 | O2: 230 | P2: 250 | Q2: 250 | R2: 250 | S2: 250 | T2: 250 | U2: 390 | V2: 420 | W2: 420
A3: 2 | B3: 70 | C3: 0 | D3: 70 | E3: 70 | F3: 70 | G3: 70 | H3: 70 | I3: 70 | J3: 70 | K3: 70 | L3: 70 | M3: 70 | N3: 230 | O3: 230 | P3: 250 | Q3: 250 | R3: 250 | S3: 250 | T3: 250 | U3: 390 | V3: 420 | W3: 420
A4: 3 | B4: 70 | C4: 70 | D4: 0 | E4: 70 | F4: 70 | G4: 70 | H4: 70 | I4: 70 | J4: 70 | K4: 70 | L4: 70 | M4: 70 | N4: 230 | O4: 230 | P4: 250 | Q4: 250 | R4: 250 | S4: 250 | T4: 250 | U4: 390 | V4: 420 | W4: 420
A5: 4 | B5: 70 | C5: 70 | D5: 70 | E5: 0 | F5: 70 | G5: 70 | H5: 70 | I5: 70 | J5: 70 | K5: 70 | L5: 70 | M5: 70 | N5: 230 | O5: 230 | P5: 250 | Q5: 250 | R5: 250 | S5: 250 | T5: 250 | U5: 390 | V5: 420 | W5: 420
A6: 5 | B6: 70 | C6: 70 | D6: 70 | E6: 70 | F6: 0 | G6: 70 | H6: 70 | I6: 70 | J6: 70 | K6: 70 | L6: 70 | M6: 70 | N6: 230 | O6: 230 | P6: 250 | Q6: 250 | R6: 250 | S6: 250 | T6: 250 | U6: 390 | V6: 420 | W6: 420
A7: 6 | B7: 70 | C7: 70 | D7: 70 | E7: 70 | F7: 70 | G7: 0 | H7: 70 | I7: 70 | J7: 70 | K7: 70 | L7: 70 | M7: 70 | N7: 230 | O7: 230 | P7: 250 | Q7: 250 | R7: 250 | S7: 250 | T7: 250 | U7: 390 | V7: 420 | W7: 420
A8: 7 | B8: 70 | C8: 70 | D8: 70 | E8: 70 | F8: 70 | G8: 70 | H8: 0 | I8: 70 | J8: 70 | K8: 70 | L8: 70 | M8: 70 | N8: 230 | O8: 230 | P8: 250 | Q8: 250 | R8: 250 | S8: 250 | T8: 250 | U8: 390 | V8: 420 | W8: 420
A9: 8 | B9: 70 | C9: 70 | D9: 70 | E9: 70 | F9: 70 | G9: 70 | H9: 70 | I9: 0 | J9: 70 | K9: 70 | L9: 70 | M9: 70 | N9: 230 | O9: 230 | P9: 250 | Q9: 250 | R9: 250 | S9: 250 | T9: 250 | U9: 390 | V9: 420 | W9: 420
A10: 9 | B10: 70 | C10: 70 | D10: 70 | E10: 70 | F10: 70 | G10: 70 | H10: 70 | I10: 70 | J10: 0 | K10: 70 | L10: 70 | M10: 70 | N10: 310 | O10: 310 | P10: 340 | Q10: 340 | R10: 340 | S10: 340 | T10: 250 | U10: 390 | V10: 420 | W10: 420
A11: 10 | B11: 70 | C11: 70 | D11: 70 | E11: 70 | F11: 70 | G11: 70 | H11: 70 | I11: 70 | J11: 70 | K11: 0 | L11: 70 | M11: 70 | N11: 310 | O11: 310 | P11: 340 | Q11: 340 | R11: 340 | S11: 340 | T11: 250 | U11: 390 | V11: 420 | W11: 420
A12: 11 | B12: 70 | C12: 70 | D12: 70 | E12: 70 | F12: 70 | G12: 70 | H12: 70 | I12: 70 | J12: 70 | K12: 70 | L12: 0 | M12: 70 | N12: 310 | O12: 310 | P12: 340 | Q12: 340 | R12: 340 | S12: 340 | T12: 250 | U12: 390 | V12: 420 | W12: 420
A13: 12 | B13: 70 | C13: 70 | D13: 70 | E13: 70 | F13: 70 | G13: 70 | H13: 70 | I13: 70 | J13: 70 | K13: 70 | L13: 70 | M13: 0 | N13: 120 | O13: 120 | P13: 340 | Q13: 340 | R13: 340 | S13: 340 | T13: 250 | U13: 390 | V13: 420 | W13: 420
... A23: 22 | B23: 420 | C23: 420 | D23: 420 | E23: 420 | F23: 420 | G23: 420 | H23: 420 | I23: 420 | J23: 420 | K23: 420 | L23: 420 | M23: 420 | N23: 350 | O23: 350 | P23: 240 | Q23: 240 | R23: 240 | S23: 240 | T23: 240 | U23: 240 | V23: 120 | W23: 0

Sheet Tren Araucanía 2025
A1: Matriz Tarifaria Adulto | Q1: Tarifa Regular con subsidio | AG1: Tarifa Regular con subsidio
A2: Estaciones | B2: Victoria | C2: PUA | D2: Perquenco | E2: Quillem | F2: Lautaro | G2: L. Centro | H2: Pillanlelbun | I2: Coleg. Claret | J2: Cajon | K2: Temuco | L2: PLC | M2: Quepe | N2: Freire | O2: Pitrufquén | Q2: Estaciones | R2: Victoria | S2: PUA | T2: Perquenco | U2: Quillem | V2: Lautaro | W2: L. Centro | X2: Pillanlelbun | Y2: Coleg. Claret | Z2: Cajon | AA2: Temuco | AB2: PLC | AC2: Quepe | AD2: Freire | AE2: Pitrufquén | AG2: Estaciones | AH2: Victoria | AI2: PUA | AJ2: Perquenco | AK2: Quillem | AL2: Lautaro | AM2: L. Centro | AN2: Pillanlelbun | AO2: Coleg. Claret | AP2: Cajon | AQ2: Temuco | AR2: PLC | AS2: Quepe | AT2: Freire | AU2: Pitrufquén
A3: Victoria | B3: 0 | C3: 950 | D3: 1200 | E3: 1200 | F3: 1200 | G3: 1200 | H3: 1200 | I3: 0 | J3: 900 | K3: 1500 | L3: 1900 | M3: 2000 | N3: 2550 | O3: 2650 | Q3: Victoria | R3: 0 | S3: 950 | T3: 1200 | U3: 1200 | V3: 1200 | W3: 1200 | X3: 1200 | Y3: 0 | Z3: 900 | AA3: 1500 | AB3: 1900 | AC3: 2000 | AD3: 2550 | AE3: 2650 | AG3: Victoria | AH3: =B3=R3 -> TRUE | AI3: =C3=S3 -> TRUE | AJ3: =D3=T3 -> TRUE | AK3: =E3=U3 -> TRUE | AL3: =F3=V3 -> TRUE | AM3: =G3=W3 -> TRUE | AN3: =H3=X3 -> TRUE | AO3: =I3=Y3 -> TRUE | ... AU3: =O3=AE3 -> TRUE
A4: PUA | B4: 950 | C4: 0 | D4: 950 | E4: 950 | F4: 950 | G4: 950 | H4: 1200 | I4: 0 | J4: 800 | K4: 1200 | L4: 1650 | M4: 1750 | N4: 2300 | O4: 2400 | Q4: PUA | R4: 950 | S4: 0 | T4: 950 | U4: 950 | V4: 950 | W4: 950 | X4: 1200 | Y4: 0 | Z4: 800 | AA4: 1200 | AB4: 1650 | AC4: 1750 | AD4: 2300 | AE4: 2400 | AG4: PUA | AH4: =B4=R4 -> TRUE | AI4: =C4=S4 -> TRUE | AJ4: =D4=T4 -> TRUE | AK4: =E4=U4 -> TRUE | AL4: =F4=V4 -> TRUE | AM4: =G4=W4 -> TRUE | AN4: =H4=X4 -> TRUE | AO4: =I4=Y4 -> TRUE | ... AU4: =O4=AE4 -> TRUE
A5: Perquenco | B5: 1200 | C5: 950 | D5: 0 | E5: 950 | F5: 950 | G5: 950 | H5: 1200 | I5: 0 | J5: 800 | K5: 1200 | L5: 1650 | M5: 1750 | N5: 2300 | O5: 2400 | Q5: Perquenco | R5: 1200 | S5: 950 | T5: 0 | U5: 950 | V5: 950 | W5: 950 | X5: 1200 | Y5: 0 | Z5: 800 | AA5: 1200 | AB5: 1650 | AC5: 1750 | AD5: 2300 | AE5: 2400 | AG5: Perquenco | AH5: =B5=R5 -> TRUE | AI5: =C5=S5 -> TRUE | AJ5: =D5=T5 -> TRUE | AK5: =E5=U5 -> TRUE | AL5: =F5=V5 -> TRUE | AM5: =G5=W5 -> TRUE | AN5: =H5=X5 -> TRUE | AO5: =I5=Y5 -> TRUE | ... AU5: =O5=AE5 -> TRUE
A6: Quillem | B6: 1200 | C6: 950 | D6: 950 | E6: 0 | F6: 950 | G6: 950 | H6: 950 | I6: 0 | J6: 700 | K6: 1200 | L6: 1650 | M6: 1750 | N6: 2300 | O6: 2400 | Q6: Quillem | R6: 1200 | S6: 950 | T6: 950 | U6: 0 | V6: 950 | W6: 950 | X6: 950 | Y6: 0 | Z6: 700 | AA6: 1200 | AB6: 1650 | AC6: 1750 | AD6: 2300 | AE6: 2400 | AG6: Quillem | AH6: =B6=R6 -> TRUE | AI6: =C6=S6 -> TRUE | AJ6: =D6=T6 -> TRUE | AK6: =E6=U6 -> TRUE | AL6: =F6=V6 -> TRUE | AM6: =G6=W6 -> TRUE | AN6: =H6=X6 -> TRUE | AO6: =I6=Y6 -> TRUE | ... AU6: =O6=AE6 -> TRUE
A7: Lautaro | B7: 1200 | C7: 950 | D7: 950 | E7: 950 | F7: 0 | G7: 950 | H7: 950 | I7: 0 | J7: 600 | K7: 1050 | L7: 1550 | M7: 1650 | N7: 2200 | O7: 2300 | Q7: Lautaro | R7: 1200 | S7: 950 | T7: 950 | U7: 950 | V7: 0 | W7: 950 | X7: 950 | Y7: 0 | Z7: 600 | AA7: 1050 | AB7: 1550 | AC7: 1650 | AD7: 2200 | AE7: 2300 | AG7: Lautaro | AH7: =B7=R7 -> TRUE | AI7: =C7=S7 -> TRUE | AJ7: =D7=T7 -> TRUE | AK7: =E7=U7 -> TRUE | AL7: =F7=V7 -> TRUE | AM7: =G7=W7 -> TRUE | AN7: =H7=X7 -> TRUE | AO7: =I7=Y7 -> TRUE | ... AU7: =O7=AE7 -> TRUE
A8: L. Centro | B8: 1200 | C8: 950 | D8: 950 | E8: 950 | F8: 950 | G8: 0 | H8: 950 | I8: 0 | J8: 600 | K8: 1050 | L8: 1550 | M8: 1650 | N8: 2200 | O8: 2300 | Q8: L. Centro | R8: 1200 | S8: 950 | T8: 950 | U8: 950 | V8: 950 | W8: 0 | X8: 950 | Y8: 0 | Z8: 600 | AA8: 1050 | AB8: 1550 | AC8: 1650 | AD8: 2200 | AE8: 2300 | AG8: L. Centro | AH8: =B8=R8 -> TRUE | AI8: =C8=S8 -> TRUE | AJ8: =D8=T8 -> TRUE | AK8: =E8=U8 -> TRUE | AL8: =F8=V8 -> TRUE | AM8: =G8=W8 -> TRUE | AN8: =H8=X8 -> TRUE | AO8: =I8=Y8 -> TRUE | ... AU8: =O8=AE8 -> TRUE
A9: Pillanlelbun | B9: 1200 | C9: 1200 | D9: 1200 | E9: 950 | F9: 950 | G9: 950 | H9: 0 | I9: 0 | J9: 600 | K9: 950 | L9: 1450 | M9: 1550 | N9: 2100 | O9: 2200 | Q9: Pillanlelbun | R9: 1200 | S9: 1200 | T9: 1200 | U9: 950 | V9: 950 | W9: 950 | X9: 0 | Y9: 0 | Z9: 600 | AA9: 950 | AB9: 1450 | AC9: 1550 | AD9: 2100 | AE9: 2200 | AG9: Pillanlelbun | AH9: =B9=R9 -> TRUE | AI9: =C9=S9 -> TRUE | AJ9: =D9=T9 -> TRUE | AK9: =E9=U9 -> TRUE | AL9: =F9=V9 -> TRUE | AM9: =G9=W9 -> TRUE | AN9: =H9=X9 -> TRUE | AO9: =I9=Y9 -> TRUE | ... AU9: =O9=AE9 -> TRUE
A10: Coleg. Claret | B10: 0 | C10: 0 | D10: 0 | E10: 0 | F10: 0 | G10: 0 | H10: 0 | I10: 0 | J10: 0 | K10: 0 | L10: 0 | M10: 0 | N10: 0 | O10: 0 | Q10: Coleg. Claret | R10: 0 | S10: 0 | T10: 0 | U10: 0 | V10: 0 | W10: 0 | X10: 0 | Y10: 0 | Z10: 0 | AA10: 1000 | AB10: 0 | AC10: 0 | AD10: 0 | AE10: 0 | AG10: Coleg. Claret | AH10: =B10=R10 -> TRUE | AI10: =C10=S10 -> TRUE | AJ10: =D10=T10 -> TRUE | AK10: =E10=U10 -> TRUE | AL10: =F10=V10 -> TRUE | AM10: =G10=W10 -> TRUE | AN10: =H10=X10 -> TRUE | AO10: =I10=Y10 -> TRUE | ... AU10: =O10=AE10 -> TRUE
A11: Cajon | B11: 900 | C11: 800 | D11: 800 | E11: 700 | F11: 600 | G11: 600 | H11: 600 | I11: 0 | J11: 0 | K11: 600 | L11: 1300 | M11: 1400 | N11: 1950 | O11: 2050 | Q11: Cajon | R11: 900 | S11: 800 | T11: 800 | U11: 700 | V11: 600 | W11: 600 | X11: 600 | Y11: 0 | Z11: 0 | AA11: 600 | AB11: 1300 | AC11: 1400 | AD11: 1950 | AE11: 2050 | AG11: Cajon | AH11: =B11=R11 -> TRUE | AI11: =C11=S11 -> TRUE | AJ11: =D11=T11 -> TRUE | AK11: =E11=U11 -> TRUE | AL11: =F11=V11 -> TRUE | AM11: =G11=W11 -> TRUE | AN11: =H11=X11 -> TRUE | AO11: =I11=Y11 -> TRUE | ... AU11: =O11=AE11 -> TRUE
A12: Temuco | B12: 1500 | C12: 1200 | D12: 1200 | E12: 1200 | F12: 1050 | G12: 1050 | H12: 950 | I12: 0 | J12: 600 | K12: 0 | L12: 700 | M12: 800 | N12: 1350 | O12: 1450 | Q12: Temuco | R12: 1500 | S12: 1200 | T12: 1200 | U12: 1200 | V12: 1050 | W12: 1050 | X12: 950 | Y12: 1000 | Z12: 600 | AA12: 0 | AB12: 700 | AC12: 800 | AD12: 1350 | AE12: 1450 | AG12: Temuco | AH12: =B12=R12 -> TRUE | AI12: =C12=S12 -> TRUE | AJ12: =D12=T12 -> TRUE | AK12: =E12=U12 -> TRUE | AL12: =F12=V12 -> TRUE | AM12: =G12=W12 -> TRUE | AN12: =H12=X12 -> TRUE | AO12: =I12=Y12 -> FALSE | ... AU12: =O12=AE12 -> TRUE
A13: PLC | B13: 1900 | C13: 1650 | D13: 1650 | E13: 1650 | F13: 1550 | G13: 1550 | H13: 1450 | I13: 0 | J13: 1300 | K13: 700 | L13: 0 | M13: 600 | N13: 1300 | O13: 1400 | Q13: PLC | R13: 1900 | S13: 1650 | T13: 1650 | U13: 1650 | V13: 1550 | W13: 1550 | X13: 1450 | Y13: 0 | Z13: 1300 | AA13: 700 | AB13: 0 | AC13: 600 | AD13: 1300 | AE13: 1400 | AG13: PLC | AH13: =B13=R13 -> TRUE | AI13: =C13=S13 -> TRUE | AJ13: =D13=T13 -> TRUE | AK13: =E13=U13 -> TRUE | AL13: =F13=V13 -> TRUE | AM13: =G13=W13 -> TRUE | AN13: =H13=X13 -> TRUE | AO13: =I13=Y13 -> TRUE | ... AU13: =O13=AE13 -> TRUE
A14: Quepe | B14: 2000 | C14: 1750 | D14: 1750 | E14: 1750 | F14: 1650 | G14: 1650 | H14: 1550 | I14: 0 | J14: 1400 | K14: 800 | L14: 600 | M14: 0 | N14: 550 | O14: 650 | Q14: Quepe | R14: 2000 | S14: 1750 | T14: 1750 | U14: 1750 | V14: 1650 | W14: 1650 | X14: 1550 | Y14: 0 | Z14: 1400 | AA14: 800 | AB14: 600 | AC14: 0 | AD14: 550 | AE14: 650 | AG14: Quepe | AH14: =B14=R14 -> TRUE | AI14: =C14=S14 -> TRUE | AJ14: =D14=T14 -> TRUE | AK14: =E14=U14 -> TRUE | AL14: =F14=V14 -> TRUE | AM14: =G14=W14 -> TRUE | AN14: =H14=X14 -> TRUE | AO14: =I14=Y14 -> TRUE | ... AU14: =O14=AE14 -> TRUE
... A16: Pitrufquén | B16: 2650 | C16: 2400 | D16: 2400 | E16: 2400 | F16: 2300 | G16: 2300 | H16: 2200 | I16: 0 | J16: 2050 | K16: 1450 | L16: 1400 | M16: 650 | N16: 600 | O16: 0 | Q16: Pitrufquén | R16: 2650 | S16: 2400 | T16: 2400 | U16: 2400 | V16: 2300 | W16: 2300 | X16: 2200 | Y16: 0 | Z16: 2050 | AA16: 1450 | AB16: 1400 | AC16: 650 | AD16: 600 | AE16: 0 | AG16: Pitrufquén | AH16: =B16=R16 -> TRUE | AI16: =C16=S16 -> TRUE | AJ16: =D16=T16 -> TRUE | AK16: =E16=U16 -> TRUE | AL16: =F16=V16 -> TRUE | AM16: =G16=W16 -> TRUE | AN16: =H16=X16 -> TRUE | AO16: =I16=Y16 -> TRUE | ... AU16: =O16=AE16 -> TRUE
Q17: 0.33 | AG17: 0.33
A18: Matriz Tarifaria Estudiantes Media y Superior | Q18: Tarifa Estudiantes con subsidio | AG18: Tarifa Estudiantes con subsidio
A19: Estaciones | B19: Victoria | C19: PUA | D19: Perquenco | E19: Quillem | F19: Lautaro | G19: L. Centro | H19: Pillanlelbun | I19: Coleg. Claret | J19: Cajon | K19: Temuco | L19: PLC | M19: Quepe | N19: Freire | O19: Pitrufquén | Q19: Estaciones | R19: Victoria | S19: PUA | T19: Perquenco | U19: Quillem | V19: Lautaro | W19: L. Centro | X19: Pillanlelbun | Y19: Coleg. Claret | Z19: Cajon | AA19: Temuco | AB19: PLC | AC19: Quepe | AD19: Freire | AE19: Pitrufquén | AG19: Estaciones | AH19: Victoria | AI19: PUA | AJ19: Perquenco | AK19: Quillem | AL19: Lautaro | AM19: L. Centro | AN19: Pillanlelbun | AO19: Coleg. Claret | AP19: Cajon | AQ19: Temuco | AR19: PLC | AS19: Quepe | AT19: Freire | AU19: Pitrufquén
A20: Victoria | B20: 0 | C20: 310 | D20: 400 | E20: 400 | F20: 400 | G20: 400 | H20: 400 | I20: 0 | J20: 300 | K20: 500 | L20: 650 | M20: 650 | N20: 850 | O20: 850 | Q20: Victoria | R20: 0 | S20: 310 | T20: 400 | U20: 400 | V20: 400 | W20: 400 | X20: 400 | Y20: 0 | Z20: 300 | AA20: 500 | AB20: 650 | AC20: 650 | AD20: 850 | AE20: 850 | AG20: Victoria | AH20: =B20=R20 -> TRUE | AI20: =C20=S20 -> TRUE | AJ20: =D20=T20 -> TRUE | AK20: =E20=U20 -> TRUE | AL20: =F20=V20 -> TRUE | AM20: =G20=W20 -> TRUE | AN20: =H20=X20 -> TRUE | AO20: =I20=Y20 -> TRUE | ... AU20: =O20=AE20 -> TRUE
A21: PUA | B21: 310 | C21: 0 | D21: 310 | E21: 310 | F21: 310 | G21: 310 | H21: 400 | I21: 0 | J21: 250 | K21: 400 | L21: 550 | M21: 600 | N21: 750 | O21: 800 | Q21: PUA | R21: 310 | S21: 0 | T21: 310 | U21: 310 | V21: 310 | W21: 310 | X21: 400 | Y21: 0 | Z21: 250 | AA21: 400 | AB21: 550 | AC21: 600 | AD21: 750 | AE21: 800 | AG21: PUA | AH21: =B21=R21 -> TRUE | AI21: =C21=S21 -> TRUE | AJ21: =D21=T21 -> TRUE | AK21: =E21=U21 -> TRUE | AL21: =F21=V21 -> TRUE | AM21: =G21=W21 -> TRUE | AN21: =H21=X21 -> TRUE | AO21: =I21=Y21 -> TRUE | ... AU21: =O21=AE21 -> TRUE
A22: Perquenco | B22: 400 | C22: 310 | D22: 0 | E22: 310 | F22: 310 | G22: 310 | H22: 400 | I22: 0 | J22: 250 | K22: 400 | L22: 550 | M22: 600 | N22: 750 | O22: 800 | Q22: Perquenco | R22: 400 | S22: 310 | T22: 0 | U22: 310 | V22: 310 | W22: 310 | X22: 400 | Y22: 0 | Z22: 250 | AA22: 400 | AB22: 550 | AC22: 600 | AD22: 750 | AE22: 800 | AG22: Perquenco | AH22: =B22=R22 -> TRUE | AI22: =C22=S22 -> TRUE | AJ22: =D22=T22 -> TRUE | AK22: =E22=U22 -> TRUE | AL22: =F22=V22 -> TRUE | AM22: =G22=W22 -> TRUE | AN22: =H22=X22 -> TRUE | AO22: =I22=Y22 -> TRUE | ... AU22: =O22=AE22 -> TRUE
A23: Quillem | B23: 400 | C23: 310 | D23: 310 | E23: 0 | F23: 310 | G23: 310 | H23: 310 | I23: 0 | J23: 250 | K23: 400 | L23: 550 | M23: 600 | N23: 750 | O23: 800 | Q23: Quillem | R23: 400 | S23: 310 | T23: 310 | U23: 0 | V23: 310 | W23: 310 | X23: 310 | Y23: 0 | Z23: 250 | AA23: 400 | AB23: 550 | AC23: 600 | AD23: 750 | AE23: 800 | AG23: Quillem | AH23: =B23=R23 -> TRUE | AI23: =C23=S23 -> TRUE | AJ23: =D23=T23 -> TRUE | AK23: =E23=U23 -> TRUE | AL23: =F23=V23 -> TRUE | AM23: =G23=W23 -> TRUE | AN23: =H23=X23 -> TRUE | AO23: =I23=Y23 -> TRUE | ... AU23: =O23=AE23 -> TRUE
A24: Lautaro | B24: 400 | C24: 310 | D24: 310 | E24: 310 | F24: 0 | G24: 310 | H24: 310 | I24: 0 | J24: 200 | K24: 350 | L24: 500 | M24: 550 | N24: 750 | O24: 750 | Q24: Lautaro | R24: 400 | S24: 310 | T24: 310 | U24: 310 | V24: 0 | W24: 310 | X24: 310 | Y24: 0 | Z24: 200 | AA24: 350 | AB24: 500 | AC24: 550 | AD24: 750 | AE24: 750 | AG24: Lautaro | AH24: =B24=R24 -> TRUE | AI24: =C24=S24 -> TRUE | AJ24: =D24=T24 -> TRUE | AK24: =E24=U24 -> TRUE | AL24: =F24=V24 -> TRUE | AM24: =G24=W24 -> TRUE | AN24: =H24=X24 -> TRUE | AO24: =I24=Y24 -> TRUE | ... AU24: =O24=AE24 -> TRUE
A25: L. Centro | B25: 400 | C25: 310 | D25: 310 | E25: 310 | F25: 310 | G25: 0 | H25: 310 | I25: 0 | J25: 200 | K25: 350 | L25: 500 | M25: 550 | N25: 750 | O25: 750 | Q25: L. Centro | R25: 400 | S25: 310 | T25: 310 | U25: 310 | V25: 310 | W25: 0 | X25: 310 | Y25: 0 | Z25: 200 | AA25: 350 | AB25: 500 | AC25: 550 | AD25: 750 | AE25: 750 | AG25: L. Centro | AH25: =B25=R25 -> TRUE | AI25: =C25=S25 -> TRUE | AJ25: =D25=T25 -> TRUE | AK25: =E25=U25 -> TRUE | AL25: =F25=V25 -> TRUE | AM25: =G25=W25 -> TRUE | AN25: =H25=X25 -> TRUE | AO25: =I25=Y25 -> TRUE | ... AU25: =O25=AE25 -> TRUE
A26: Pillanlelbun | B26: 400 | C26: 400 | D26: 400 | E26: 310 | F26: 310 | G26: 310 | H26: 0 | I26: 0 | J26: 200 | K26: 310 | L26: 500 | M26: 500 | N26: 700 | O26: 750 | Q26: Pillanlelbun | R26: 400 | S26: 400 | T26: 400 | U26: 310 | V26: 310 | W26: 310 | X26: 0 | Y26: 0 | Z26: 200 | AA26: 310 | AB26: 500 | AC26: 500 | AD26: 700 | AE26: 750 | AG26: Pillanlelbun | AH26: =B26=R26 -> TRUE | AI26: =C26=S26 -> TRUE | AJ26: =D26=T26 -> TRUE | AK26: =E26=U26 -> TRUE | AL26: =F26=V26 -> TRUE | AM26: =G26=W26 -> TRUE | AN26: =H26=X26 -> TRUE | AO26: =I26=Y26 -> TRUE | ... AU26: =O26=AE26 -> TRUE
A27: Coleg. Claret | B27: 0 | C27: 0 | D27: 0 | E27: 0 | F27: 0 | G27: 0 | H27: 0 | I27: 0 | J27: 0 | K27: 330 | L27: 0 | M27: 0 | N27: 0 | O27: 0 | Q27: Coleg. Claret | R27: 0 | S27: 0 | T27: 0 | U27: 0 | V27: 0 | W27: 0 | X27: 0 | Y27: 0 | Z27: 0 | AA27: 330 | AB27: 0 | AC27: 0 | AD27: 0 | AE27: 0 | AG27: Coleg. Claret | AH27: =B27=R27 -> TRUE | AI27: =C27=S27 -> TRUE | AJ27: =D27=T27 -> TRUE | AK27: =E27=U27 -> TRUE | AL27: =F27=V27 -> TRUE | AM27: =G27=W27 -> TRUE | AN27: =H27=X27 -> TRUE | AO27: =I27=Y27 -> TRUE | ... AU27: =O27=AE27 -> TRUE
A28: Cajon | B28: 300 | C28: 250 | D28: 250 | E28: 250 | F28: 200 | G28: 200 | H28: 200 | I28: 0 | J28: 0 | K28: 200 | L28: 450 | M28: 450 | N28: 650 | O28: 700 | Q28: Cajon | R28: 300 | S28: 250 | T28: 250 | U28: 250 | V28: 200 | W28: 200 | X28: 200 | Y28: 0 | Z28: 0 | AA28: 200 | AB28: 450 | AC28: 450 | AD28: 650 | AE28: 700 | AG28: Cajon | AH28: =B28=R28 -> TRUE | AI28: =C28=S28 -> TRUE | AJ28: =D28=T28 -> TRUE | AK28: =E28=U28 -> TRUE | AL28: =F28=V28 -> TRUE | AM28: =G28=W28 -> TRUE | AN28: =H28=X28 -> TRUE | AO28: =I28=Y28 -> TRUE | ... AU28: =O28=AE28 -> TRUE
A29: Temuco | B29: 500 | C29: 400 | D29: 400 | E29: 400 | F29: 350 | G29: 350 | H29: 310 | I29: 330 | J29: 200 | K29: 0 | L29: 250 | M29: 250 | N29: 450 | O29: 500 | Q29: Temuco | R29: 500 | S29: 400 | T29: 400 | U29: 400 | V29: 350 | W29: 350 | X29: 310 | Y29: 330 | Z29: 200 | AA29: 0 | AB29: 250 | AC29: 250 | AD29: 450 | AE29: 500 | AG29: Temuco | AH29: =B29=R29 -> TRUE | AI29: =C29=S29 -> TRUE | AJ29: =D29=T29 -> TRUE | AK29: =E29=U29 -> TRUE | AL29: =F29=V29 -> TRUE | AM29: =G29=W29 -> TRUE | AN29: =H29=X29 -> TRUE | AO29: =I29=Y29 -> TRUE | ... AU29: =O29=AE29 -> TRUE
A30: PLC | B30: 650 | C30: 550 | D30: 550 | E30: 550 | F30: 500 | G30: 500 | H30: 500 | I30: 0 | J30: 450 | K30: 250 | L30: 0 | M30: 200 | N30: 450 | O30: 450 | Q30: PLC | R30: 650 | S30: 550 | T30: 550 | U30: 550 | V30: 500 | W30: 500 | X30: 500 | Y30: 0 | Z30: 450 | AA30: 250 | AB30: 0 | AC30: 200 | AD30: 450 | AE30: 450 | AG30: PLC | AH30: =B30=R30 -> TRUE | AI30: =C30=S30 -> TRUE | AJ30: =D30=T30 -> TRUE | AK30: =E30=U30 -> TRUE | AL30: =F30=V30 -> TRUE | AM30: =G30=W30 -> TRUE | AN30: =H30=X30 -> TRUE | AO30: =I30=Y30 -> TRUE | ... AU30: =O30=AE30 -> TRUE
A31: Quepe | B31: 650 | C31: 600 | D31: 600 | E31: 600 | F31: 550 | G31: 550 | H31: 500 | I31: 0 | J31: 450 | K31: 250 | L31: 200 | M31: 0 | N31: 200 | O31: 200 | Q31: Quepe | R31: 650 | S31: 600 | T31: 600 | U31: 600 | V31: 550 | W31: 550 | X31: 500 | Y31: 0 | Z31: 450 | AA31: 250 | AB31: 200 | AC31: 0 | AD31: 200 | AE31: 200 | AG31: Quepe | AH31: =B31=R31 -> TRUE | AI31: =C31=S31 -> TRUE | AJ31: =D31=T31 -> TRUE | AK31: =E31=U31 -> TRUE | AL31: =F31=V31 -> TRUE | AM31: =G31=W31 -> TRUE | AN31: =H31=X31 -> TRUE | AO31: =I31=Y31 -> TRUE | ... AU31: =O31=AE31 -> TRUE
... A33: Pitrufquén | B33: 850 | C33: 800 | D33: 800 | E33: 800 | F33: 750 | G33: 750 | H33: 750 | I33: 0 | J33: 700 | K33: 500 | L33: 450 | M33: 200 | N33: 200 | O33: 0 | Q33: Pitrufquén | R33: 850 | S33: 800 | T33: 800 | U33: 800 | V33: 750 | W33: 750 | X33: 750 | Y33: 0 | Z33: 700 | AA33: 500 | AB33: 450 | AC33: 200 | AD33: 200 | AE33: 0 | AG33: Pitrufquén | AH33: =B33=R33 -> TRUE | AI33: =C33=S33 -> TRUE | AJ33: =D33=T33 -> TRUE | AK33: =E33=U33 -> TRUE | AL33: =F33=V33 -> TRUE | AM33: =G33=W33 -> TRUE | AN33: =H33=X33 -> TRUE | AO33: =I33=Y33 -> TRUE | ... AU33: =O33=AE33 -> TRUE
Q34: 0.5 | AG34: 0.5
A35: Matriz Tarifaria Tercera Edad | Q35: Tarifa Adulto Mayor con subsidio | AG35: Tarifa Adulto Mayor con subsidio
A36: Estaciones | B36: Victoria | C36: PUA | D36: Perquenco | E36: Quillem | F36: Lautaro | G36: L. Centro | H36: Pillanlelbun | I36: Coleg. Claret | J36: Cajon | K36: Temuco | L36: PLC | M36: Quepe | N36: Freire | O36: Pitrufquén | Q36: Estaciones | R36: Victoria | S36: PUA | T36: Perquenco | U36: Quillem | V36: Lautaro | W36: L. Centro | X36: Pillanlelbun | Y36: Coleg. Claret | Z36: Cajon | AA36: Temuco | AB36: PLC | AC36: Quepe | AD36: Freire | AE36: Pitrufquén | AG36: Estaciones | AH36: Victoria | AI36: PUA | AJ36: Perquenco | AK36: Quillem | AL36: Lautaro | AM36: L. Centro | AN36: Pillanlelbun | AO36: Coleg. Claret | AP36: Cajon | AQ36: Temuco | AR36: PLC | AS36: Quepe | AT36: Freire | AU36: Pitrufquén
A37: Victoria | B37: 0 | C37: 480 | D37: 600 | E37: 600 | F37: 600 | G37: 600 | H37: 600 | I37: 0 | J37: 450 | K37: 750 | L37: 950 | M37: 1000 | N37: 1300 | O37: 1350 | Q37: Victoria | R37: 0 | S37: 480 | T37: 600 | U37: 600 | V37: 600 | W37: 600 | X37: 600 | Y37: 0 | Z37: 450 | AA37: 750 | AB37: 950 | AC37: 1000 | AD37: 1300 | AE37: 1350 | AG37: Victoria | AH37: =B37=R37 -> TRUE | AI37: =C37=S37 -> TRUE | AJ37: =D37=T37 -> TRUE | AK37: =E37=U37 -> TRUE | AL37: =F37=V37 -> TRUE | AM37: =G37=W37 -> TRUE | AN37: =H37=X37 -> TRUE | AO37: =I37=Y37 -> TRUE | ... AU37: =O37=AE37 -> TRUE
A38: PUA | B38: 480 | C38: 0 | D38: 480 | E38: 480 | F38: 480 | G38: 480 | H38: 600 | I38: 0 | J38: 400 | K38: 600 | L38: 850 | M38: 900 | N38: 1150 | O38: 1200 | Q38: PUA | R38: 480 | S38: 0 | T38: 480 | U38: 480 | V38: 480 | W38: 480 | X38: 600 | Y38: 0 | Z38: 400 | AA38: 600 | AB38: 850 | AC38: 900 | AD38: 1150 | AE38: 1200 | AG38: PUA | AH38: =B38=R38 -> TRUE | AI38: =C38=S38 -> TRUE | AJ38: =D38=T38 -> TRUE | AK38: =E38=U38 -> TRUE | AL38: =F38=V38 -> TRUE | AM38: =G38=W38 -> TRUE | AN38: =H38=X38 -> TRUE | AO38: =I38=Y38 -> TRUE | ... AU38: =O38=AE38 -> TRUE
A39: Perquenco | B39: 600 | C39: 480 | D39: 0 | E39: 480 | F39: 480 | G39: 480 | H39: 600 | I39: 0 | J39: 400 | K39: 600 | L39: 850 | M39: 900 | N39: 1150 | O39: 1200 | Q39: Perquenco | R39: 600 | S39: 480 | T39: 0 | U39: 480 | V39: 480 | W39: 480 | X39: 600 | Y39: 0 | Z39: 400 | AA39: 600 | AB39: 850 | AC39: 900 | AD39: 1150 | AE39: 1200 | AG39: Perquenco | AH39: =B39=R39 -> TRUE | AI39: =C39=S39 -> TRUE | AJ39: =D39=T39 -> TRUE | AK39: =E39=U39 -> TRUE | AL39: =F39=V39 -> TRUE | AM39: =G39=W39 -> TRUE | AN39: =H39=X39 -> TRUE | AO39: =I39=Y39 -> TRUE | ... AU39: =O39=AE39 -> TRUE
A40: Quillem | B40: 600 | C40: 480 | D40: 480 | E40: 0 | F40: 480 | G40: 480 | H40: 480 | I40: 0 | J40: 350 | K40: 600 | L40: 850 | M40: 900 | N40: 1150 | O40: 1200 | Q40: Quillem | R40: 600 | S40: 480 | T40: 480 | U40: 0 | V40: 480 | W40: 480 | X40: 480 | Y40: 0 | Z40: 350 | AA40: 600 | AB40: 850 | AC40: 900 | AD40: 1150 | AE40: 1200 | AG40: Quillem | AH40: =B40=R40 -> TRUE | AI40: =C40=S40 -> TRUE | AJ40: =D40=T40 -> TRUE | AK40: =E40=U40 -> TRUE | AL40: =F40=V40 -> TRUE | AM40: =G40=W40 -> TRUE | AN40: =H40=X40 -> TRUE | AO40: =I40=Y40 -> TRUE | ... AU40: =O40=AE40 -> TRUE
A41: Lautaro | B41: 600 | C41: 480 | D41: 480 | E41: 480 | F41: 0 | G41: 480 | H41: 480 | I41: 0 | J41: 300 | K41: 530 | L41: 800 | M41: 850 | N41: 1100 | O41: 1150 | Q41: Lautaro | R41: 600 | S41: 480 | T41: 480 | U41: 480 | V41: 0 | W41: 480 | X41: 480 | Y41: 0 | Z41: 300 | AA41: 530 | AB41: 800 | AC41: 850 | AD41: 1100 | AE41: 1150 | AG41: Lautaro | AH41: =B41=R41 -> TRUE | AI41: =C41=S41 -> TRUE | AJ41: =D41=T41 -> TRUE | AK41: =E41=U41 -> TRUE | AL41: =F41=V41 -> TRUE | AM41: =G41=W41 -> TRUE | AN41: =H41=X41 -> TRUE | AO41: =I41=Y41 -> TRUE | ... AU41: =O41=AE41 -> TRUE
A42: L. Centro | B42: 600 | C42: 480 | D42: 480 | E42: 480 | F42: 480 | G42: 0 | H42: 480 | I42: 0 | J42: 300 | K42: 530 | L42: 800 | M42: 850 | N42: 1100 | O42: 1150 | Q42: L. Centro | R42: 600 | S42: 480 | T42: 480 | U42: 480 | V42: 480 | W42: 0 | X42: 480 | Y42: 0 | Z42: 300 | AA42: 530 | AB42: 800 | AC42: 850 | AD42: 1100 | AE42: 1150 | AG42: L. Centro | AH42: =B42=R42 -> TRUE | AI42: =C42=S42 -> TRUE | AJ42: =D42=T42 -> TRUE | AK42: =E42=U42 -> TRUE | AL42: =F42=V42 -> TRUE | AM42: =G42=W42 -> TRUE | AN42: =H42=X42 -> TRUE | AO42: =I42=Y42 -> TRUE | ... AU42: =O42=AE42 -> TRUE
...

Sheet Biotren 2024
A1: ZONA | B1: PASAJERO COMÚN
B2: 1 | C2: 2 | D2: 3 | E2: 4 | F2: 5 | G2: 6 | H2: 7 | I2: 8 | J2: 9 | K2: 10
A3: 1 | B3: 340 | C3: 400 | D3: 450 | E3: 460 | F3: 480 | G3: 480 | H3: 490 | I3: 770 | J3: 820 | K3: 830 | O3: ZONA 1 | P3: HUALQUI
A4: 2 | B4: 400 | C4: 340 | D4: 420 | E4: 450 | F4: 460 | G4: 470 | H4: 480 | I4: 760 | J4: 770 | K4: 770
A5: 3 | B5: 450 | C5: 420 | D5: 340 | E5: 400 | F5: 450 | G5: 450 | H5: 460 | I5: 720 | J5: 720 | K5: 740 | O5: ZONA 2 | P5: LA LEONERA
A6: 4 | B6: 460 | C6: 450 | D6: 400 | E6: 340 | F6: 400 | G6: 440 | H6: 480 | I6: 730 | J6: 740 | K6: 760 | P6: MANQUIMÁVIDA
A7: 5 | B7: 480 | C7: 460 | D7: 450 | E7: 400 | F7: 340 | G7: 440 | H7: 480 | I7: 740 | J7: 760 | K7: 770 | P7: PEDRO MEDINA
A8: 6 | B8: 480 | C8: 470 | D8: 450 | E8: 440 | F8: 440 | G8: 340 | H8: 420 | I8: 530 | J8: 560 | K8: 670 | P8: CHIGUAYANTE
A9: 7 | B9: 490 | C9: 480 | D9: 460 | E9: 480 | F9: 480 | G9: 420 | H9: 340 | I9: 490 | J9: 510 | K9: 530
A10: 8 | B10: 770 | C10: 760 | D10: 720 | E10: 730 | F10: 740 | G10: 530 | H10: 490 | I10: 340 | J10: 360 | K10: 440 | O10: ZONA 3 | P10: CONCEPCIÓN
A11: 9 | B11: 820 | C11: 770 | D11: 720 | E11: 740 | F11: 760 | G11: 560 | H11: 510 | I11: 360 | J11: 340 | K11: 350 | P11: LORENZO ARENAS
A12: 10 | B12: 830 | C12: 770 | D12: 740 | E12: 760 | F12: 770 | G12: 670 | H12: 530 | I12: 440 | J12: 350 | K12: 340
O13: ZONA 4 | P13: UTFSM
P14: LOS CÓNDORES
A15: ZONA | B15: ESTUDIANTE MEDIA / SUPERIOR | P15: HIGUERAS
B16: 1 | C16: 2 | D16: 3 | E16: 4 | F16: 5 | G16: 6 | H16: 7 | I16: 8 | J16: 9 | K16: 10
A17: 1 | B17: 110 | C17: 140 | D17: 150 | E17: 160 | F17: 160 | G17: 160 | H17: 170 | I17: 260 | J17: 270 | K17: 280 | O17: ZONA 5 | P17: EL ARENAL
A18: 2 | B18: 140 | C18: 110 | D18: 140 | E18: 150 | F18: 160 | G18: 160 | H18: 160 | I18: 250 | J18: 260 | K18: 260 | P18: MERCADO DE THNO
A19: 3 | B19: 150 | C19: 140 | D19: 110 | E19: 140 | F19: 150 | G19: 150 | H19: 160 | I19: 240 | J19: 240 | K19: 250
A20: 4 | B20: 160 | C20: 150 | D20: 140 | E20: 110 | F20: 140 | G20: 150 | H20: 160 | I20: 240 | J20: 250 | K20: 250 | O20: ZONA 6 | P20: JUAN PABLO II
A21: 5 | B21: 160 | C21: 160 | D21: 150 | E21: 140 | F21: 110 | G21: 150 | H21: 160 | I21: 250 | J21: 250 | K21: 260 | P21: DIAGONAL BIOBÍO
A22: 6 | B22: 160 | C22: 160 | D22: 150 | E22: 150 | F22: 150 | G22: 110 | H22: 140 | I22: 180 | J22: 190 | K22: 230 | P22: ALBORADA
A23: 7 | B23: 170 | C23: 160 | D23: 160 | E23: 160 | F23: 160 | G23: 140 | H23: 110 | I23: 170 | J23: 170 | K23: 180
A24: 8 | B24: 260 | C24: 250 | D24: 240 | E24: 240 | F24: 250 | G24: 180 | H24: 170 | I24: 110 | J24: 120 | K24: 150 | O24: ZONA 7 | P24: COSTA MAR
A25: 9 | B25: 270 | C25: 260 | D25: 240 | E25: 250 | F25: 250 | G25: 190 | H25: 170 | I25: 120 | J25: 110 | K25: 120 | P25: EL PARQUE
A26: 10 | B26: 280 | C26: 260 | D26: 250 | E26: 250 | F26: 260 | G26: 230 | H26: 180 | I26: 150 | J26: 120 | K26: 110 | P26: LOMAS COLORADAS
P27: CARDENAL RAÚL SILVA HENRÍQUEZ
A28: ZONA | B28: TERCERA EDAD
B29: 1 | C29: 2 | D29: 3 | E29: 4 | F29: 5 | G29: 6 | H29: 7 | I29: 8 | J29: 9 | K29: 10 | O29: ZONA 8 | P29: HITO GALVARINO
A30: 1 | B30: 170 | C30: 200 | D30: 230 | E30: 230 | F30: 240 | G30: 240 | H30: 250 | I30: 390 | J30: 410 | K30: 420 | P30: LOS CANELOS
A31: 2 | B31: 200 | C31: 170 | D31: 210 | E31: 230 | F31: 230 | G31: 240 | H31: 240 | I31: 380 | J31: 390 | K31: 390
A32: 3 | B32: 230 | C32: 210 | D32: 170 | E32: 200 | F32: 230 | G32: 230 | H32: 230 | I32: 360 | J32: 360 | K32: 370 | O32: ZONA 9 | P32: HUINCA
A33: 4 | B33: 230 | C33: 230 | D33: 200 | E33: 170 | F33: 200 | G33: 220 | H33: 240 | I33: 370 | J33: 370 | K33: 380 | P33: CRISTO REDENTOR
A34: 5 | B34: 240 | C34: 230 | D34: 230 | E34: 200 | F34: 170 | G34: 220 | H34: 240 | I34: 370 | J34: 380 | K34: 390
A35: 6 | B35: 240 | C35: 240 | D35: 230 | E35: 220 | F35: 220 | G35: 170 | H35: 210 | I35: 270 | J35: 280 | K35: 340 | O35: ZONA 10 | P35: LAGUNA QUIÑENCO
A36: 7 | B36: 250 | C36: 240 | D36: 230 | E36: 240 | F36: 240 | G36: 210 | H36: 170 | I36: 250 | J36: 260 | K36: 270 | P36: CORONEL
A37: 8 | B37: 390 | C37: 380 | D37: 360 | E37: 370 | F37: 370 | G37: 270 | H37: 250 | I37: 170 | J37: 180 | K37: 220
A38: 9 | B38: 410 | C38: 390 | D38: 360 | E38: 370 | F38: 380 | G38: 280 | H38: 260 | I38: 180 | J38: 170 | K38: 180
A39: 10 | B39: 420 | C39: 390 | D39: 370 | E39: 380 | F39: 390 | G39: 340 | H39: 270 | I39: 220 | J39: 180 | K39: 170

Sheet BT-25 por Estación
A1: Matriz Tarifaria Adulto
A2: Estaciones | B2: Hualqui | C2: Leonera | D2: Manquimavida | E2: Pedro Medina | F2: Chiguayante | G2: Concepcion | H2: Lorenzo Arenas | I2: UTFSM | J2: Los Condores | K2: Higueras | L2: Arenal | M2: Mercado | N2: Juan Pablo II | O2: Diagonal Bio Bio | P2: Alborada | Q2: Costa Mar | R2: El Parque | S2: Lomas Coloradas | T2: Raul Silva H. | U2: Hito Galvarino | V2: Los Canelos | W2: Huinca | X2: Cristo Redentor | Y2: Lag.Quiñenco | Z2: Coronel | AB2: Estaciones | AC2: Hualqui | AD2: Leonera | AE2: Manquimavida | AF2: Pedro Medina | AG2: Chiguayante | AH2: Concepcion | AI2: Lorenzo Arenas | AJ2: UTFSM | AK2: Los Condores | AL2: Higueras | AM2: Arenal | AN2: Mercado | AO2: Juan Pablo II | AP2: Diagonal Bio Bio | AQ2: Alborada | AR2: Costa Mar | AS2: El Parque | AT2: Lomas Coloradas | AU2: Raul Silva H. | AV2: Hito Galvarino | AW2: Los Canelos | AX2: Huinca | AY2: Cristo Redentor | AZ2: Lag.Quiñenco | BA2: Coronel | BC2: Estaciones | BD2: Hualqui | BE2: Leonera | BF2: Manquimavida | BG2: Pedro Medina | BH2: Chiguayante | BI2: Concepcion | BJ2: Lorenzo Arenas | BK2: UTFSM | BL2: Los Condores | BM2: Higueras | BN2: Arenal | BO2: Mercado | BP2: Juan Pablo II | BQ2: Diagonal Bio Bio | BR2: Alborada | BS2: Costa Mar | BT2: El Parque | BU2: Lomas Coloradas | BV2: Raul Silva H. | BW2: Hito Galvarino | BX2: Los Canelos | BY2: Huinca | BZ2: Cristo Redentor | CA2: Lag.Quiñenco | CB2: Coronel
A3: Hualqui | B3: 380 | C3: 450 | D3: 450 | E3: 450 | F3: 450 | G3: 500 | H3: 500 | I3: 510 | J3: 510 | K3: 510 | L3: 530 | M3: 530 | N3: 530 | O3: 530 | P3: 530 | Q3: 540 | R3: 540 | S3: 540 | T3: 540 | U3: 840 | V3: 840 | W3: 890 | X3: 890 | Y3: 900 | Z3: 900 | AB3: Hualqui | AC3: 340 | AD3: 400 | AE3: 400 | AF3: 400 | AG3: 400 | AH3: 450 | AI3: 450 | AJ3: 460 | AK3: 460 | AL3: 460 | AM3: 480 | AN3: 480 | AO3: 480 | AP3: 480 | AQ3: 480 | AR3: 490 | AS3: 490 | AT3: 490 | AU3: 490 | AV3: 770 | AW3: 770 | AX3: 820 | AY3: 820 | AZ3: 830 | BA3: 830 | BC3: Hualqui | BD3: =B3-AC3 -> 40 | BE3: =C3-AD3 -> 50 | BF3: =D3-AE3 -> 50 | BG3: =E3-AF3 -> 50 | BH3: =F3-AG3 -> 50 | BI3: =G3-AH3 -> 50 | BJ3: =H3-AI3 -> 50 | BK3: =I3-AJ3 -> 50 | ... CB3: =Z3-BA3 -> 70
A4: Leonera | B4: 450 | C4: 380 | D4: 380 | E4: 380 | F4: 380 | G4: 470 | H4: 470 | I4: 500 | J4: 500 | K4: 500 | L4: 510 | M4: 510 | N4: 520 | O4: 520 | P4: 520 | Q4: 530 | R4: 530 | S4: 530 | T4: 530 | U4: 830 | V4: 830 | W4: 840 | X4: 840 | Y4: 840 | Z4: 840 | AB4: Leonera | AC4: 400 | AD4: 340 | AE4: 340 | AF4: 340 | AG4: 340 | AH4: 420 | AI4: 420 | AJ4: 450 | AK4: 450 | AL4: 450 | AM4: 460 | AN4: 460 | AO4: 470 | AP4: 470 | AQ4: 470 | AR4: 480 | AS4: 480 | AT4: 480 | AU4: 480 | AV4: 760 | AW4: 760 | AX4: 770 | AY4: 770 | AZ4: 770 | BA4: 770 | BC4: Leonera | BD4: =B4-AC4 -> 50 | BE4: =C4-AD4 -> 40 | BF4: =D4-AE4 -> 40 | BG4: =E4-AF4 -> 40 | BH4: =F4-AG4 -> 40 | BI4: =G4-AH4 -> 50 | BJ4: =H4-AI4 -> 50 | BK4: =I4-AJ4 -> 50 | ... CB4: =Z4-BA4 -> 70
A5: Manquimavida | B5: 450 | C5: 380 | D5: 380 | E5: 380 | F5: 380 | G5: 470 | H5: 470 | I5: 500 | J5: 500 | K5: 500 | L5: 510 | M5: 510 | N5: 520 | O5: 520 | P5: 520 | Q5: 530 | R5: 530 | S5: 530 | T5: 530 | U5: 830 | V5: 830 | W5: 840 | X5: 840 | Y5: 840 | Z5: 840 | AB5: Manquimavida | AC5: 400 | AD5: 340 | AE5: 340 | AF5: 340 | AG5: 340 | AH5: 420 | AI5: 420 | AJ5: 450 | AK5: 450 | AL5: 450 | AM5: 460 | AN5: 460 | AO5: 470 | AP5: 470 | AQ5: 470 | AR5: 480 | AS5: 480 | AT5: 480 | AU5: 480 | AV5: 760 | AW5: 760 | AX5: 770 | AY5: 770 | AZ5: 770 | BA5: 770 | BC5: Manquimavida | BD5: =B5-AC5 -> 50 | BE5: =C5-AD5 -> 40 | BF5: =D5-AE5 -> 40 | BG5: =E5-AF5 -> 40 | BH5: =F5-AG5 -> 40 | BI5: =G5-AH5 -> 50 | BJ5: =H5-AI5 -> 50 | BK5: =I5-AJ5 -> 50 | ... CB5: =Z5-BA5 -> 70
A6: Pedro Medina | B6: 450 | C6: 380 | D6: 380 | E6: 380 | F6: 380 | G6: 470 | H6: 470 | I6: 500 | J6: 500 | K6: 500 | L6: 510 | M6: 510 | N6: 520 | O6: 520 | P6: 520 | Q6: 530 | R6: 530 | S6: 530 | T6: 530 | U6: 830 | V6: 830 | W6: 840 | X6: 840 | Y6: 840 | Z6: 840 | AB6: Pedro Medina | AC6: 400 | AD6: 340 | AE6: 340 | AF6: 340 | AG6: 340 | AH6: 420 | AI6: 420 | AJ6: 450 | AK6: 450 | AL6: 450 | AM6: 460 | AN6: 460 | AO6: 470 | AP6: 470 | AQ6: 470 | AR6: 480 | AS6: 480 | AT6: 480 | AU6: 480 | AV6: 760 | AW6: 760 | AX6: 770 | AY6: 770 | AZ6: 770 | BA6: 770 | BC6: Pedro Medina | BD6: =B6-AC6 -> 50 | BE6: =C6-AD6 -> 40 | BF6: =D6-AE6 -> 40 | BG6: =E6-AF6 -> 40 | BH6: =F6-AG6 -> 40 | BI6: =G6-AH6 -> 50 | BJ6: =H6-AI6 -> 50 | BK6: =I6-AJ6 -> 50 | ... CB6: =Z6-BA6 -> 70
A7: Chiguayante | B7: 450 | C7: 380 | D7: 380 | E7: 380 | F7: 380 | G7: 470 | H7: 470 | I7: 500 | J7: 500 | K7: 500 | L7: 510 | M7: 510 | N7: 520 | O7: 520 | P7: 520 | Q7: 530 | R7: 530 | S7: 530 | T7: 530 | U7: 830 | V7: 830 | W7: 840 | X7: 840 | Y7: 840 | Z7: 840 | AB7: Chiguayante | AC7: 400 | AD7: 340 | AE7: 340 | AF7: 340 | AG7: 340 | AH7: 420 | AI7: 420 | AJ7: 450 | AK7: 450 | AL7: 450 | AM7: 460 | AN7: 460 | AO7: 470 | AP7: 470 | AQ7: 470 | AR7: 480 | AS7: 480 | AT7: 480 | AU7: 480 | AV7: 760 | AW7: 760 | AX7: 770 | AY7: 770 | AZ7: 770 | BA7: 770 | BC7: Chiguayante | BD7: =B7-AC7 -> 50 | BE7: =C7-AD7 -> 40 | BF7: =D7-AE7 -> 40 | BG7: =E7-AF7 -> 40 | BH7: =F7-AG7 -> 40 | BI7: =G7-AH7 -> 50 | BJ7: =H7-AI7 -> 50 | BK7: =I7-AJ7 -> 50 | ... CB7: =Z7-BA7 -> 70
A8: Concepcion | B8: 500 | C8: 470 | D8: 470 | E8: 470 | F8: 470 | G8: 380 | H8: 380 | I8: 450 | J8: 450 | K8: 450 | L8: 500 | M8: 500 | N8: 500 | O8: 500 | P8: 500 | Q8: 510 | R8: 510 | S8: 510 | T8: 510 | U8: 780 | V8: 780 | W8: 780 | X8: 780 | Y8: 810 | Z8: 810 | AB8: Concepcion | AC8: 450 | AD8: 420 | AE8: 420 | AF8: 420 | AG8: 420 | AH8: 340 | AI8: 340 | AJ8: 400 | AK8: 400 | AL8: 400 | AM8: 450 | AN8: 450 | AO8: 450 | AP8: 450 | AQ8: 450 | AR8: 460 | AS8: 460 | AT8: 460 | AU8: 460 | AV8: 720 | AW8: 720 | AX8: 720 | AY8: 720 | AZ8: 740 | BA8: 740 | BC8: Concepcion | BD8: =B8-AC8 -> 50 | BE8: =C8-AD8 -> 50 | BF8: =D8-AE8 -> 50 | BG8: =E8-AF8 -> 50 | BH8: =F8-AG8 -> 50 | BI8: =G8-AH8 -> 40 | BJ8: =H8-AI8 -> 40 | BK8: =I8-AJ8 -> 50 | ... CB8: =Z8-BA8 -> 70
A9: Lorenzo Arenas | B9: 500 | C9: 470 | D9: 470 | E9: 470 | F9: 470 | G9: 380 | H9: 380 | I9: 450 | J9: 450 | K9: 450 | L9: 500 | M9: 500 | N9: 500 | O9: 500 | P9: 500 | Q9: 510 | R9: 510 | S9: 510 | T9: 510 | U9: 780 | V9: 780 | W9: 780 | X9: 780 | Y9: 810 | Z9: 810 | AB9: Lorenzo Arenas | AC9: 450 | AD9: 420 | AE9: 420 | AF9: 420 | AG9: 420 | AH9: 340 | AI9: 340 | AJ9: 400 | AK9: 400 | AL9: 400 | AM9: 450 | AN9: 450 | AO9: 450 | AP9: 450 | AQ9: 450 | AR9: 460 | AS9: 460 | AT9: 460 | AU9: 460 | AV9: 720 | AW9: 720 | AX9: 720 | AY9: 720 | AZ9: 740 | BA9: 740 | BC9: Lorenzo Arenas | BD9: =B9-AC9 -> 50 | BE9: =C9-AD9 -> 50 | BF9: =D9-AE9 -> 50 | BG9: =E9-AF9 -> 50 | BH9: =F9-AG9 -> 50 | BI9: =G9-AH9 -> 40 | BJ9: =H9-AI9 -> 40 | BK9: =I9-AJ9 -> 50 | ... CB9: =Z9-BA9 -> 70
A10: UTFSM | B10: 510 | C10: 500 | D10: 500 | E10: 500 | F10: 500 | G10: 450 | H10: 450 | I10: 380 | J10: 380 | K10: 380 | L10: 450 | M10: 450 | N10: 490 | O10: 490 | P10: 490 | Q10: 530 | R10: 530 | S10: 530 | T10: 530 | U10: 800 | V10: 800 | W10: 810 | X10: 810 | Y10: 830 | Z10: 830 | AB10: UTFSM | AC10: 460 | AD10: 450 | AE10: 450 | AF10: 450 | AG10: 450 | AH10: 400 | AI10: 400 | AJ10: 340 | AK10: 340 | AL10: 340 | AM10: 400 | AN10: 400 | AO10: 440 | AP10: 440 | AQ10: 440 | AR10: 480 | AS10: 480 | AT10: 480 | AU10: 480 | AV10: 730 | AW10: 730 | AX10: 740 | AY10: 740 | AZ10: 760 | BA10: 760 | BC10: UTFSM | BD10: =B10-AC10 -> 50 | BE10: =C10-AD10 -> 50 | BF10: =D10-AE10 -> 50 | BG10: =E10-AF10 -> 50 | BH10: =F10-AG10 -> 50 | BI10: =G10-AH10 -> 50 | BJ10: =H10-AI10 -> 50 | BK10: =I10-AJ10 -> 40 | ... CB10: =Z10-BA10 -> 70
A11: Los Condores | B11: 510 | C11: 500 | D11: 500 | E11: 500 | F11: 500 | G11: 450 | H11: 450 | I11: 380 | J11: 380 | K11: 380 | L11: 450 | M11: 450 | N11: 490 | O11: 490 | P11: 490 | Q11: 530 | R11: 530 | S11: 530 | T11: 530 | U11: 800 | V11: 800 | W11: 810 | X11: 810 | Y11: 830 | Z11: 830 | AB11: Los Condores | AC11: 460 | AD11: 450 | AE11: 450 | AF11: 450 | AG11: 450 | AH11: 400 | AI11: 400 | AJ11: 340 | AK11: 340 | AL11: 340 | AM11: 400 | AN11: 400 | AO11: 440 | AP11: 440 | AQ11: 440 | AR11: 480 | AS11: 480 | AT11: 480 | AU11: 480 | AV11: 730 | AW11: 730 | AX11: 740 | AY11: 740 | AZ11: 760 | BA11: 760 | BC11: Los Condores | BD11: =B11-AC11 -> 50 | BE11: =C11-AD11 -> 50 | BF11: =D11-AE11 -> 50 | BG11: =E11-AF11 -> 50 | BH11: =F11-AG11 -> 50 | BI11: =G11-AH11 -> 50 | BJ11: =H11-AI11 -> 50 | BK11: =I11-AJ11 -> 40 | ... CB11: =Z11-BA11 -> 70
A12: Higueras | B12: 510 | C12: 500 | D12: 500 | E12: 500 | F12: 500 | G12: 450 | H12: 450 | I12: 380 | J12: 380 | K12: 380 | L12: 450 | M12: 450 | N12: 490 | O12: 490 | P12: 490 | Q12: 530 | R12: 530 | S12: 530 | T12: 530 | U12: 800 | V12: 800 | W12: 810 | X12: 810 | Y12: 830 | Z12: 830 | AB12: Higueras | AC12: 460 | AD12: 450 | AE12: 450 | AF12: 450 | AG12: 450 | AH12: 400 | AI12: 400 | AJ12: 340 | AK12: 340 | AL12: 340 | AM12: 400 | AN12: 400 | AO12: 440 | AP12: 440 | AQ12: 440 | AR12: 480 | AS12: 480 | AT12: 480 | AU12: 480 | AV12: 730 | AW12: 730 | AX12: 740 | AY12: 740 | AZ12: 760 | BA12: 760 | BC12: Higueras | BD12: =B12-AC12 -> 50 | BE12: =C12-AD12 -> 50 | BF12: =D12-AE12 -> 50 | BG12: =E12-AF12 -> 50 | BH12: =F12-AG12 -> 50 | BI12: =G12-AH12 -> 50 | BJ12: =H12-AI12 -> 50 | BK12: =I12-AJ12 -> 40 | ... CB12: =Z12-BA12 -> 70
A13: Arenal | B13: 530 | C13: 510 | D13: 510 | E13: 510 | F13: 510 | G13: 500 | H13: 500 | I13: 450 | J13: 450 | K13: 450 | L13: 380 | M13: 380 | N13: 490 | O13: 490 | P13: 490 | Q13: 530 | R13: 530 | S13: 530 | T13: 530 | U13: 810 | V13: 810 | W13: 830 | X13: 830 | Y13: 840 | Z13: 840 | AB13: Arenal | AC13: 480 | AD13: 460 | AE13: 460 | AF13: 460 | AG13: 460 | AH13: 450 | AI13: 450 | AJ13: 400 | AK13: 400 | AL13: 400 | AM13: 340 | AN13: 340 | AO13: 440 | AP13: 440 | AQ13: 440 | AR13: 480 | AS13: 480 | AT13: 480 | AU13: 480 | AV13: 740 | AW13: 740 | AX13: 760 | AY13: 760 | AZ13: 770 | BA13: 770 | BC13: Arenal | BD13: =B13-AC13 -> 50 | BE13: =C13-AD13 -> 50 | BF13: =D13-AE13 -> 50 | BG13: =E13-AF13 -> 50 | BH13: =F13-AG13 -> 50 | BI13: =G13-AH13 -> 50 | BJ13: =H13-AI13 -> 50 | BK13: =I13-AJ13 -> 50 | ... CB13: =Z13-BA13 -> 70
A14: Mercado | B14: 530 | C14: 510 | D14: 510 | E14: 510 | F14: 510 | G14: 500 | H14: 500 | I14: 450 | J14: 450 | K14: 450 | L14: 380 | M14: 380 | N14: 490 | O14: 490 | P14: 490 | Q14: 530 | R14: 530 | S14: 530 | T14: 530 | U14: 810 | V14: 810 | W14: 830 | X14: 830 | Y14: 840 | Z14: 840 | AB14: Mercado | AC14: 480 | AD14: 460 | AE14: 460 | AF14: 460 | AG14: 460 | AH14: 450 | AI14: 450 | AJ14: 400 | AK14: 400 | AL14: 400 | AM14: 340 | AN14: 340 | AO14: 440 | AP14: 440 | AQ14: 440 | AR14: 480 | AS14: 480 | AT14: 480 | AU14: 480 | AV14: 740 | AW14: 740 | AX14: 760 | AY14: 760 | AZ14: 770 | BA14: 770 | BC14: Mercado | BD14: =B14-AC14 -> 50 | BE14: =C14-AD14 -> 50 | BF14: =D14-AE14 -> 50 | BG14: =E14-AF14 -> 50 | BH14: =F14-AG14 -> 50 | BI14: =G14-AH14 -> 50 | BJ14: =H14-AI14 -> 50 | BK14: =I14-AJ14 -> 50 | ... CB14: =Z14-BA14 -> 70
... A27: Coronel | B27: 900 | C27: 840 | D27: 840 | E27: 840 | F27: 840 | G27: 810 | H27: 810 | I27: 830 | J27: 830 | K27: 830 | L27: 840 | M27: 840 | N27: 730 | O27: 730 | P27: 730 | Q27: 580 | R27: 580 | S27: 580 | T27: 580 | U27: 490 | V27: 490 | W27: 390 | X27: 390 | Y27: 380 | Z27: 380 | AB27: Coronel | AC27: 830 | AD27: 770 | AE27: 770 | AF27: 770 | AG27: 770 | AH27: 740 | AI27: 740 | AJ27: 760 | AK27: 760 | AL27: 760 | AM27: 770 | AN27: 770 | AO27: 670 | AP27: 670 | AQ27: 670 | AR27: 530 | AS27: 530 | AT27: 530 | AU27: 530 | AV27: 440 | AW27: 440 | AX27: 350 | AY27: 350 | AZ27: 340 | BA27: 340 | BC27: Coronel | BD27: =B27-AC27 -> 70 | BE27: =C27-AD27 -> 70 | BF27: =D27-AE27 -> 70 | BG27: =E27-AF27 -> 70 | BH27: =F27-AG27 -> 70 | BI27: =G27-AH27 -> 70 | BJ27: =H27-AI27 -> 70 | BK27: =I27-AJ27 -> 70 | ... CB27: =Z27-BA27 -> 40
A29: Matriz Tarifaria Estudiante
A30: Estaciones | B30: Hualqui | C30: Leonera | D30: Manquimavida | E30: Pedro Medina | F30: Chiguayante | G30: Concepcion | H30: Lorenzo Arenas | I30: UTFSM | J30: Los Condores | K30: Higueras | L30: Arenal | M30: Mercado | N30: Juan Pablo II | O30: Diagonal Bio Bio | P30: Alborada | Q30: Costa Mar | R30: El Parque | S30: Lomas Coloradas | T30: Raul Silva H. | U30: Hito Galvarino | V30: Los Canelos | W30: Huinca | X30: Cristo Redentor | Y30: Lag.Quiñenco | Z30: Coronel | AB30: Estaciones | AC30: Hualqui | AD30: Leonera | AE30: Manquimavida | AF30: Pedro Medina | AG30: Chiguayante | AH30: Concepcion | AI30: Lorenzo Arenas | AJ30: UTFSM | AK30: Los Condores | AL30: Higueras | AM30: Arenal | AN30: Mercado | AO30: Juan Pablo II | AP30: Diagonal Bio Bio | AQ30: Alborada | AR30: Costa Mar | AS30: El Parque | AT30: Lomas Coloradas | AU30: Raul Silva H. | AV30: Hito Galvarino | AW30: Los Canelos | AX30: Huinca | AY30: Cristo Redentor | AZ30: Lag.Quiñenco | BA30: Coronel | BC30: Estaciones | BD30: Hualqui | BE30: Leonera | BF30: Manquimavida | BG30: Pedro Medina | BH30: Chiguayante | BI30: Concepcion | BJ30: Lorenzo Arenas | BK30: UTFSM | BL30: Los Condores | BM30: Higueras | BN30: Arenal | BO30: Mercado | BP30: Juan Pablo II | BQ30: Diagonal Bio Bio | BR30: Alborada | BS30: Costa Mar | BT30: El Parque | BU30: Lomas Coloradas | BV30: Raul Silva H. | BW30: Hito Galvarino | BX30: Los Canelos | BY30: Huinca | BZ30: Cristo Redentor | CA30: Lag.Quiñenco | CB30: Coronel
A31: Hualqui | B31: 130 | C31: 150 | D31: 150 | E31: 150 | F31: 150 | G31: 170 | H31: 170 | I31: 170 | J31: 170 | K31: 170 | L31: 170 | M31: 170 | N31: 170 | O31: 170 | P31: 170 | Q31: 180 | R31: 180 | S31: 180 | T31: 180 | U31: 280 | V31: 280 | W31: 290 | X31: 290 | Y31: 300 | Z31: 300 | AB31: Hualqui | AC31: 110 | AD31: 130 | AE31: 130 | AF31: 130 | AG31: 130 | AH31: 150 | AI31: 150 | AJ31: 160 | AK31: 160 | AL31: 160 | AM31: 160 | AN31: 160 | AO31: 160 | AP31: 160 | AQ31: 160 | AR31: 170 | AS31: 170 | AT31: 170 | AU31: 170 | AV31: 260 | AW31: 260 | AX31: 270 | AY31: 270 | AZ31: 280 | BA31: 280 | BC31: Hualqui | BD31: 110 | BE31: 130 | BF31: 130 | BG31: 130 | BH31: 130 | BI31: 150 | BJ31: 150 | BK31: 160 | BL31: 160 | BM31: 160 | BN31: 160 | BO31: 160 | BP31: 160 | BQ31: 160 | BR31: 160 | BS31: 170 | BT31: 170 | BU31: 170 | BV31: 170 | BW31: 260 | BX31: 260 | BY31: 270 | BZ31: 270 | CA31: 280 | CB31: 280
A32: Leonera | B32: 150 | C32: 130 | D32: 130 | E32: 130 | F32: 130 | G32: 160 | H32: 160 | I32: 170 | J32: 170 | K32: 170 | L32: 170 | M32: 170 | N32: 170 | O32: 170 | P32: 170 | Q32: 170 | R32: 170 | S32: 170 | T32: 170 | U32: 270 | V32: 270 | W32: 280 | X32: 280 | Y32: 280 | Z32: 280 | AB32: Leonera | AC32: 130 | AD32: 110 | AE32: 110 | AF32: 110 | AG32: 110 | AH32: 140 | AI32: 140 | AJ32: 150 | AK32: 150 | AL32: 150 | AM32: 160 | AN32: 160 | AO32: 160 | AP32: 160 | AQ32: 160 | AR32: 160 | AS32: 160 | AT32: 160 | AU32: 160 | AV32: 250 | AW32: 250 | AX32: 260 | AY32: 260 | AZ32: 260 | BA32: 260 | BC32: Leonera | BD32: 130 | BE32: 110 | BF32: 110 | BG32: 110 | BH32: 110 | BI32: 140 | BJ32: 140 | BK32: 150 | BL32: 150 | BM32: 150 | BN32: 160 | BO32: 160 | BP32: 160 | BQ32: 160 | BR32: 160 | BS32: 160 | BT32: 160 | BU32: 160 | BV32: 160 | BW32: 250 | BX32: 250 | BY32: 260 | BZ32: 260 | CA32: 260 | CB32: 260
A33: Manquimavida | B33: 150 | C33: 130 | D33: 130 | E33: 130 | F33: 130 | G33: 160 | H33: 160 | I33: 170 | J33: 170 | K33: 170 | L33: 170 | M33: 170 | N33: 170 | O33: 170 | P33: 170 | Q33: 170 | R33: 170 | S33: 170 | T33: 170 | U33: 270 | V33: 270 | W33: 280 | X33: 280 | Y33: 280 | Z33: 280 | AB33: Manquimavida | AC33: 130 | AD33: 110 | AE33: 110 | AF33: 110 | AG33: 110 | AH33: 140 | AI33: 140 | AJ33: 150 | AK33: 150 | AL33: 150 | AM33: 160 | AN33: 160 | AO33: 160 | AP33: 160 | AQ33: 160 | AR33: 160 | AS33: 160 | AT33: 160 | AU33: 160 | AV33: 250 | AW33: 250 | AX33: 260 | AY33: 260 | AZ33: 260 | BA33: 260 | BC33: Manquimavida | BD33: 130 | BE33: 110 | BF33: 110 | BG33: 110 | BH33: 110 | BI33: 140 | BJ33: 140 | BK33: 150 | BL33: 150 | BM33: 150 | BN33: 160 | BO33: 160 | BP33: 160 | BQ33: 160 | BR33: 160 | BS33: 160 | BT33: 160 | BU33: 160 | BV33: 160 | BW33: 250 | BX33: 250 | BY33: 260 | BZ33: 260 | CA33: 260 | CB33: 260
A34: Pedro Medina | B34: 150 | C34: 130 | D34: 130 | E34: 130 | F34: 130 | G34: 160 | H34: 160 | I34: 170 | J34: 170 | K34: 170 | L34: 170 | M34: 170 | N34: 170 | O34: 170 | P34: 170 | Q34: 170 | R34: 170 | S34: 170 | T34: 170 | U34: 270 | V34: 270 | W34: 280 | X34: 280 | Y34: 280 | Z34: 280 | AB34: Pedro Medina | AC34: 130 | AD34: 110 | AE34: 110 | AF34: 110 | AG34: 110 | AH34: 140 | AI34: 140 | AJ34: 150 | AK34: 150 | AL34: 150 | AM34: 160 | AN34: 160 | AO34: 160 | AP34: 160 | AQ34: 160 | AR34: 160 | AS34: 160 | AT34: 160 | AU34: 160 | AV34: 250 | AW34: 250 | AX34: 260 | AY34: 260 | AZ34: 260 | BA34: 260 | BC34: Pedro Medina | BD34: 130 | BE34: 110 | BF34: 110 | BG34: 110 | BH34: 110 | BI34: 140 | BJ34: 140 | BK34: 150 | BL34: 150 | BM34: 150 | BN34: 160 | BO34: 160 | BP34: 160 | BQ34: 160 | BR34: 160 | BS34: 160 | BT34: 160 | BU34: 160 | BV34: 160 | BW34: 250 | BX34: 250 | BY34: 260 | BZ34: 260 | CA34: 260 | CB34: 260
A35: Chiguayante | B35: 150 | C35: 130 | D35: 130 | E35: 130 | F35: 130 | G35: 160 | H35: 160 | I35: 170 | J35: 170 | K35: 170 | L35: 170 | M35: 170 | N35: 170 | O35: 170 | P35: 170 | Q35: 170 | R35: 170 | S35: 170 | T35: 170 | U35: 270 | V35: 270 | W35: 280 | X35: 280 | Y35: 280 | Z35: 280 | AB35: Chiguayante | AC35: 130 | AD35: 110 | AE35: 110 | AF35: 110 | AG35: 110 | AH35: 140 | AI35: 140 | AJ35: 150 | AK35: 150 | AL35: 150 | AM35: 160 | AN35: 160 | AO35: 160 | AP35: 160 | AQ35: 160 | AR35: 160 | AS35: 160 | AT35: 160 | AU35: 160 | AV35: 250 | AW35: 250 | AX35: 260 | AY35: 260 | AZ35: 260 | BA35: 260 | BC35: Chiguayante | BD35: 130 | BE35: 110 | BF35: 110 | BG35: 110 | BH35: 110 | BI35: 140 | BJ35: 140 | BK35: 150 | BL35: 150 | BM35: 150 | BN35: 160 | BO35: 160 | BP35: 160 | BQ35: 160 | BR35: 160 | BS35: 160 | BT35: 160 | BU35: 160 | BV35: 160 | BW35: 250 | BX35: 250 | BY35: 260 | BZ35: 260 | CA35: 260 | CB35: 260
A36: Concepcion | B36: 170 | C36: 160 | D36: 160 | E36: 160 | F36: 160 | G36: 130 | H36: 130 | I36: 150 | J36: 150 | K36: 150 | L36: 170 | M36: 170 | N36: 170 | O36: 170 | P36: 170 | Q36: 170 | R36: 170 | S36: 170 | T36: 170 | U36: 260 | V36: 260 | W36: 260 | X36: 260 | Y36: 270 | Z36: 270 | AB36: Concepcion | AC36: 150 | AD36: 140 | AE36: 140 | AF36: 140 | AG36: 140 | AH36: 110 | AI36: 110 | AJ36: 130 | AK36: 130 | AL36: 130 | AM36: 150 | AN36: 150 | AO36: 150 | AP36: 150 | AQ36: 150 | AR36: 160 | AS36: 160 | AT36: 160 | AU36: 160 | AV36: 240 | AW36: 240 | AX36: 240 | AY36: 240 | AZ36: 250 | BA36: 250 | BC36: Concepcion | BD36: 150 | BE36: 140 | BF36: 140 | BG36: 140 | BH36: 140 | BI36: 110 | BJ36: 110 | BK36: 130 | BL36: 130 | BM36: 130 | BN36: 150 | BO36: 150 | BP36: 150 | BQ36: 150 | BR36: 150 | BS36: 160 | BT36: 160 | BU36: 160 | BV36: 160 | BW36: 240 | BX36: 240 | BY36: 240 | BZ36: 240 | CA36: 250 | CB36: 250
A37: Lorenzo Arenas | B37: 170 | C37: 160 | D37: 160 | E37: 160 | F37: 160 | G37: 130 | H37: 130 | I37: 150 | J37: 150 | K37: 150 | L37: 170 | M37: 170 | N37: 170 | O37: 170 | P37: 170 | Q37: 170 | R37: 170 | S37: 170 | T37: 170 | U37: 260 | V37: 260 | W37: 260 | X37: 260 | Y37: 270 | Z37: 270 | AB37: Lorenzo Arenas | AC37: 150 | AD37: 140 | AE37: 140 | AF37: 140 | AG37: 140 | AH37: 110 | AI37: 110 | AJ37: 130 | AK37: 130 | AL37: 130 | AM37: 150 | AN37: 150 | AO37: 150 | AP37: 150 | AQ37: 150 | AR37: 160 | AS37: 160 | AT37: 160 | AU37: 160 | AV37: 240 | AW37: 240 | AX37: 240 | AY37: 240 | AZ37: 250 | BA37: 250 | BC37: Lorenzo Arenas | BD37: 150 | BE37: 140 | BF37: 140 | BG37: 140 | BH37: 140 | BI37: 110 | BJ37: 110 | BK37: 130 | BL37: 130 | BM37: 130 | BN37: 150 | BO37: 150 | BP37: 150 | BQ37: 150 | BR37: 150 | BS37: 160 | BT37: 160 | BU37: 160 | BV37: 160 | BW37: 240 | BX37: 240 | BY37: 240 | BZ37: 240 | CA37: 250 | CB37: 250
